Workbook
Name A: H.HÀ!$1:$1048576

Sheet TK 14 NHÃN
A1: Mã sản phẩm cha | B1: Tên sản phẩm cha | C1: Mã | D1: Mã vạch | E1: Sản phẩm | F1: Tồn hiện tại | G1: Tổng tồn | H1: TĐK.Số lượng | I1: NTK.Số lượng | J1: XTK.Số lượng | K1: TCK.Số lượng | M1: TK HẾT 6/4/2026
C2: LV3652-2022 | D2: 2000200245995 | E2: Ốp HH 30*60 - LV3652 A1 (1h= 1.44m) | F2: 1038 | G2: 1038 | H2: 0 | I2: 29579 | J2: 28541 | K2: 1038
C3: LV3658 A1 - 2022 | D3: 2000200196525 | E3: Ốp 30*60- LV3658 A1 ( 1 hộp = 1.44m2) | F3: 245 | G3: 245 | H3: 0 | I3: 28292 | J3: 28047 | K3: 245
C4: N0366-1012 A1 ( vàng) | D4: 2000167122933 | E4: Gạch ceramic N6-1012 A1 ( 1 hộp = 1.44m2) | F4: 190 | G4: 190 | H4: 0 | I4: 15755 | J4: 15565 | K4: 190
C5: N0355-1007C A1 | D5: 2000166291678 | E5: Gạch Nise (50x50) 5-1007C A1 ( 1 hộp =1.5m2) | F5: -2 | G5: -2 | H5: 0 | I5: 14093 | J5: 14095 | K5: -2
C6: LX36000 A1 - 2021 ( TT) | D6: 2000177074130 | E6: ốp trắng LX36000 A1 ( 1 hộp =1.44m2) | F6: 463 | G6: 463 | H6: 0 | I6: 13341 | J6: 12878 | K6: 463
C7: LX36601 A1(1h=8v=1.44m2) | D7: 2000214251203 | E7: Gạch 30*60 HH khói trắng phẳng mã LX36601 A1(1h=8v=1.44m2) | F7: 734 | G7: 734 | H7: 0 | I7: 13112 | J7: 12378 | K7: 734
C8: N6-6036 A1 - 2022 | D8: 2000199504578 | E8: Gạch Porcelain N6-6036 A1 ( 1 hộp = 1.44m2) | F8: 282 | G8: 282 | H8: 0 | I8: 12952 | J8: 12670 | K8: 282
C9: N6-1016 A1 | D9: 2000201169184 | E9: Gạch ceramic N6-1016 A1 ( 1 hộp = 1.44m2) | F9: 7 | G9: 7 | H9: 0 | I9: 12164 | J9: 12157 | K9: 7
C10: LV3600 A1 -2022 | D10: 2000198912534 | E10: Ốp LV3600 A1 ( 1 hộp = 8v=1.44m2) | F10: 777 | G10: 777 | H10: 0 | I10: 11354 | J10: 10577 | K10: 777
C11: N0366-6007 A1 ( bán sứ - vàng nhạt) | D11: 2000167123572 | E11: Gạch Pocelain N6-6007 A1 ( 1 hộp = 1.44m2) | F11: 183 | G11: 183 | H11: 0 | I11: 10931 | J11: 10748 | K11: 183
C12: Ceramic N0366-1001 - 57 | D12: 2000171991143 | E12: Gạch Ceramic N6-1001 A1 ( 1 hộp = 1.44m2) | F12: 117 | G12: 117 | H12: 0 | I12: 9630 | J12: 9513 | K12: 117
C13: LX5516 A1-2021 | D13: 2000192608440 | E13: Sân vườn LX5516 A1 (1h=6v= 1.5m2) | F13: 633 | G13: 633 | H13: 0 | I13: 9460 | J13: 8827 | K13: 633
... C1333: MN612.616 A1 - VIÊN | D1333: 2000214257434 | E1333: Gạch Nise kích thước 60*120 mã MN612.616 A1 - VIÊN | F1333: -1 | G1333: -1 | H1333: 0 | I1333: 0 | J1333: 1 | K1333: -1

Sheet H.HÀ
B1: TÊN SP | C1: TỒN CK 30,9.2026 | D1: TỒN HIỆN TẠI T10.2026 | E1: 1 | G1: =1+E1 -> 2 | I1: =1+G1 -> 3 | K1: =1+I1 -> 4 | M1: 5 | O1: =1+M1 -> 6 | Q1: =1+O1 -> 7 | S1: =1+Q1 -> 8 | U1: =1+S1 -> 9 | W1: =1+U1 -> 10 | Y1: =1+W1 -> 11 | AA1: =1+Y1 -> 12 | AC1: =1+AA1 -> 13 | AE1: =1+AC1 -> 14 | AG1: =1+AE1 -> 15 | AI1: =1+AG1 -> 16 | AK1: =1+AI1 -> 17 | AM1: =1+AK1 -> 18 | AO1: =1+AM1 -> 19 | AQ1: =1+AO1 -> 20 | AS1: =1+AQ1 -> 21 | AU1: =1+AS1 -> 22 | AW1: =1+AU1 -> 23 | AY1: =1+AW1 -> 24 | BA1: =1+AY1 -> 25 | BC1: =1+BA1 -> 26 | BE1: =1+BC1 -> 27 | BG1: =1+BE1 -> 28 | BI1: =1+BG1 -> 29 | BK1: =1+BI1 -> 30 | BM1: =1+BK1 -> 31 | BO1: thiếu hụt k rõ nguyên nhân | BQ1: TỔNG | BS1: M2/H | BT1: QUY M2 | BU1: ĐƠN GIÁ/m | BV1: THÀNH TIỀN
A2: TỔNG CỘNG | C2: =SUM(C5:C292) -> 23200.924 | D2: =SUM(D5:D292) -> 21719.924 | E2: N | F2: X | G2: N | H2: X | I2: N | J2: X | K2: N | L2: X | M2: N | N2: X | O2: N | P2: X | Q2: N | R2: X | S2: N | T2: X | U2: N | V2: X | W2: N | X2: X | Y2: N | Z2: X | AA2: N | AB2: X | AC2: N | AD2: X | AE2: N | AF2: X | AG2: N | AH2: X | AI2: N | AJ2: X | AK2: N | AL2: X | AM2: N | AN2: X | AO2: N | AP2: X | AQ2: N | AR2: X | AS2: N | AT2: X | AU2: N | AV2: X | AW2: N | AX2: X | AY2: N | AZ2: X | BA2: N | BB2: X | BC2: N | BD2: X | BE2: N | BF2: X | BG2: N | BH2: X | BI2: N | BJ2: X | BK2: N | BL2: X | BM2: N | BN2: X | BO2: N | BP2: X | BQ2: N | BR2: X | BS2: 340.82 | BT2: =SUM(BT5:BT241) -> 31091.37 | BV2: =SUM(BV5:BV241) -> 2.6100715e+09
E3: =SUM(E4:E295) -> 0 | F3: =SUM(F4:F295) -> 68 | G3: =SUM(G4:G295) -> 3 | H3: =SUM(H4:H295) -> 562 | I3: =SUM(I4:I295) -> 0 | J3: =SUM(J4:J295) -> 279 | K3: =SUM(K4:K295) -> 0 | L3: =SUM(L4:L295) -> 105 | ... BP3: =SUM(BP4:BP295) -> 11 | BQ3: =+E3+G3+I3+K3+M3+O3+Q3+S3+U3+W3+Y3+AA3+AC3+AE3+AG3+AI3+AK3+AM3+AO3+AQ3+AS3+AU3+AW3+AY3+BA3+BC3+BE3+BG3+BI3+BK3+BM3+BO3 -> 15 | BR3: =+F3+H3+J3+L3+N3+P3+R3+T3+V3+X3+Z3+AB3+AD3+AF3+AH3+AJ3+AL3+AN3+AP3+AR3+AT3+AV3+AX3+AZ3+BB3+BD3+BF3+BH3+BJ3+BL3+BN3+BP3 -> 1496
E4: 0 | BQ4: =+E4+G4+I4+K4+M4+O4+Q4+S4+U4+W4+Y4+AA4+AC4+AE4+AG4+AI4+AK4+AM4+AO4+AQ4+AS4+AU4+AW4+AY4+BA4+BC4+BE4+BG4+BI4+BK4+BM4+BO4 -> 0 | BR4: =+F4+H4+J4+L4+N4+P4+R4+T4+V4+X4+Z4+AB4+AD4+AF4+AH4+AJ4+AL4+AN4+AP4+AR4+AT4+AV4+AX4+AZ4+BB4+BD4+BF4+BH4+BJ4+BL4+BN4+BP4 -> 0
A5: GẠCH 1 MÉT | B5: LP10,104 | C5: 49 | D5: =C5+BQ5-BR5 -> 46 | H5: 3 | BQ5: =+E5+G5+I5+K5+M5+O5+Q5+S5+U5+W5+Y5+AA5+AC5+AE5+AG5+AI5+AK5+AM5+AO5+AQ5+AS5+AU5+AW5+AY5+BA5+BC5+BE5+BG5+BI5+BK5+BM5+BO5 -> 0 | BR5: =+F5+H5+J5+L5+N5+P5+R5+T5+V5+X5+Z5+AB5+AD5+AF5+AH5+AJ5+AL5+AN5+AP5+AR5+AT5+AV5+AX5+AZ5+BB5+BD5+BF5+BH5+BJ5+BL5+BN5+BP5 -> 3 | BS5: 2 | BT5: =+BS5*D5 -> 92 | BU5: 136000 | BV5: =+BU5*BT5 -> 12512000
B6: LP10,112 | C6: 115 | D6: =C6+BQ6-BR6 -> 112 | H6: 3 | BQ6: =+E6+G6+I6+K6+M6+O6+Q6+S6+U6+W6+Y6+AA6+AC6+AE6+AG6+AI6+AK6+AM6+AO6+AQ6+AS6+AU6+AW6+AY6+BA6+BC6+BE6+BG6+BI6+BK6+BM6+BO6 -> 0 | BR6: =+F6+H6+J6+L6+N6+P6+R6+T6+V6+X6+Z6+AB6+AD6+AF6+AH6+AJ6+AL6+AN6+AP6+AR6+AT6+AV6+AX6+AZ6+BB6+BD6+BF6+BH6+BJ6+BL6+BN6+BP6 -> 3 | BS6: 2 | BT6: =+BS6*D6 -> 224 | BU6: 136000 | BV6: =+BU6*BT6 -> 30464000
B7: LP10,113 | C7: 61 | D7: =C7+BQ7-BR7 -> 58 | H7: 3 | BQ7: =+E7+G7+I7+K7+M7+O7+Q7+S7+U7+W7+Y7+AA7+AC7+AE7+AG7+AI7+AK7+AM7+AO7+AQ7+AS7+AU7+AW7+AY7+BA7+BC7+BE7+BG7+BI7+BK7+BM7+BO7 -> 0 | BR7: =+F7+H7+J7+L7+N7+P7+R7+T7+V7+X7+Z7+AB7+AD7+AF7+AH7+AJ7+AL7+AN7+AP7+AR7+AT7+AV7+AX7+AZ7+BB7+BD7+BF7+BH7+BJ7+BL7+BN7+BP7 -> 3 | BS7: 2 | BT7: =+BS7*D7 -> 116 | BU7: 136000 | BV7: =+BU7*BT7 -> 15776000
B8: LP10,114 | C8: 113 | D8: =C8+BQ8-BR8 -> 110 | H8: 3 | BQ8: =+E8+G8+I8+K8+M8+O8+Q8+S8+U8+W8+Y8+AA8+AC8+AE8+AG8+AI8+AK8+AM8+AO8+AQ8+AS8+AU8+AW8+AY8+BA8+BC8+BE8+BG8+BI8+BK8+BM8+BO8 -> 0 | BR8: =+F8+H8+J8+L8+N8+P8+R8+T8+V8+X8+Z8+AB8+AD8+AF8+AH8+AJ8+AL8+AN8+AP8+AR8+AT8+AV8+AX8+AZ8+BB8+BD8+BF8+BH8+BJ8+BL8+BN8+BP8 -> 3 | BS8: 2 | BT8: =+BS8*D8 -> 220 | BU8: 136000 | BV8: =+BU8*BT8 -> 29920000
C9: 0 | D9: =C9+BQ9-BR9 -> 0 | BQ9: =+E9+G9+I9+K9+M9+O9+Q9+S9+U9+W9+Y9+AA9+AC9+AE9+AG9+AI9+AK9+AM9+AO9+AQ9+AS9+AU9+AW9+AY9+BA9+BC9+BE9+BG9+BI9+BK9+BM9+BO9 -> 0 | BR9: =+F9+H9+J9+L9+N9+P9+R9+T9+V9+X9+Z9+AB9+AD9+AF9+AH9+AJ9+AL9+AN9+AP9+AR9+AT9+AV9+AX9+AZ9+BB9+BD9+BF9+BH9+BJ9+BL9+BN9+BP9 -> 0 | BT9: =+BS9*D9 -> 0 | BV9: =+BU9*BT9 -> 0
A10: GẠCH 80 MỚI | B10: LP18,112 -A2 | C10: 462 | D10: =C10+BQ10-BR10 -> 302 | J10: 160 | BQ10: =+E10+G10+I10+K10+M10+O10+Q10+S10+U10+W10+Y10+AA10+AC10+AE10+AG10+AI10+AK10+AM10+AO10+AQ10+AS10+AU10+AW10+AY10+BA10+BC10+BE10+BG10+BI10+BK10+BM10+BO10 -> 0 | BR10: =+F10+H10+J10+L10+N10+P10+R10+T10+V10+X10+Z10+AB10+AD10+AF10+AH10+AJ10+AL10+AN10+AP10+AR10+AT10+AV10+AX10+AZ10+BB10+BD10+BF10+BH10+BJ10+BL10+BN10+BP10 -> 160 | BS10: 1.92 | BT10: =+BS10*D10 -> 579.84 | BU10: 95000 | BV10: =+BU10*BT10 -> 55084800
B11: LP18,113 - A2 | C11: 0 | D11: =C11+BQ11-BR11 -> 0 | BQ11: =+E11+G11+I11+K11+M11+O11+Q11+S11+U11+W11+Y11+AA11+AC11+AE11+AG11+AI11+AK11+AM11+AO11+AQ11+AS11+AU11+AW11+AY11+BA11+BC11+BE11+BG11+BI11+BK11+BM11+BO11 -> 0 | BR11: =+F11+H11+J11+L11+N11+P11+R11+T11+V11+X11+Z11+AB11+AD11+AF11+AH11+AJ11+AL11+AN11+AP11+AR11+AT11+AV11+AX11+AZ11+BB11+BD11+BF11+BH11+BJ11+BL11+BN11+BP11 -> 0 | BS11: 1.92 | BT11: =+BS11*D11 -> 0 | BU11: 95000 | BV11: =+BU11*BT11 -> 0
B12: LP18,114 -A2 | C12: 0 | D12: =C12+BQ12-BR12 -> 0 | BQ12: =+E12+G12+I12+K12+M12+O12+Q12+S12+U12+W12+Y12+AA12+AC12+AE12+AG12+AI12+AK12+AM12+AO12+AQ12+AS12+AU12+AW12+AY12+BA12+BC12+BE12+BG12+BI12+BK12+BM12+BO12 -> 0 | BR12: =+F12+H12+J12+L12+N12+P12+R12+T12+V12+X12+Z12+AB12+AD12+AF12+AH12+AJ12+AL12+AN12+AP12+AR12+AT12+AV12+AX12+AZ12+BB12+BD12+BF12+BH12+BJ12+BL12+BN12+BP12 -> 0 | BS12: 1.92 | BT12: =+BS12*D12 -> 0 | BU12: 95000 | BV12: =+BU12*BT12 -> 0
C13: 0 | D13: =C13+BQ13-BR13 -> 0 | BQ13: =+E13+G13+I13+K13+M13+O13+Q13+S13+U13+W13+Y13+AA13+AC13+AE13+AG13+AI13+AK13+AM13+AO13+AQ13+AS13+AU13+AW13+AY13+BA13+BC13+BE13+BG13+BI13+BK13+BM13+BO13 -> 0 | BR13: =+F13+H13+J13+L13+N13+P13+R13+T13+V13+X13+Z13+AB13+AD13+AF13+AH13+AJ13+AL13+AN13+AP13+AR13+AT13+AV13+AX13+AZ13+BB13+BD13+BF13+BH13+BJ13+BL13+BN13+BP13 -> 0 | BS13: 1.92 | BT13: =+BS13*D13 -> 0 | BV13: =+BU13*BT13 -> 0
B14: LP18,112 A1 | C14: 122 | D14: =C14+BQ14-BR14 -> 120 | H14: 2 | BQ14: =+E14+G14+I14+K14+M14+O14+Q14+S14+U14+W14+Y14+AA14+AC14+AE14+AG14+AI14+AK14+AM14+AO14+AQ14+AS14+AU14+AW14+AY14+BA14+BC14+BE14+BG14+BI14+BK14+BM14+BO14 -> 0 | BR14: =+F14+H14+J14+L14+N14+P14+R14+T14+V14+X14+Z14+AB14+AD14+AF14+AH14+AJ14+AL14+AN14+AP14+AR14+AT14+AV14+AX14+AZ14+BB14+BD14+BF14+BH14+BJ14+BL14+BN14+BP14 -> 2 | BS14: 1.92 | BT14: =+BS14*D14 -> 230.4 | BU14: 115200 | BV14: =+BU14*BT14 -> 26542080
B15: LP18,113 A1 | C15: 85 | D15: =C15+BQ15-BR15 -> 80 | H15: =1+2 -> 3 | J15: 2 | BQ15: =+E15+G15+I15+K15+M15+O15+Q15+S15+U15+W15+Y15+AA15+AC15+AE15+AG15+AI15+AK15+AM15+AO15+AQ15+AS15+AU15+AW15+AY15+BA15+BC15+BE15+BG15+BI15+BK15+BM15+BO15 -> 0 | BR15: =+F15+H15+J15+L15+N15+P15+R15+T15+V15+X15+Z15+AB15+AD15+AF15+AH15+AJ15+AL15+AN15+AP15+AR15+AT15+AV15+AX15+AZ15+BB15+BD15+BF15+BH15+BJ15+BL15+BN15+BP15 -> 5 | BS15: 1.92 | BT15: =+BS15*D15 -> 153.6 | BU15: 115200 | BV15: =+BU15*BT15 -> 17694720
B16: LP18,114 A1 | C16: 160 | D16: =C16+BQ16-BR16 -> 158 | H16: 2 | BQ16: =+E16+G16+I16+K16+M16+O16+Q16+S16+U16+W16+Y16+AA16+AC16+AE16+AG16+AI16+AK16+AM16+AO16+AQ16+AS16+AU16+AW16+AY16+BA16+BC16+BE16+BG16+BI16+BK16+BM16+BO16 -> 0 | BR16: =+F16+H16+J16+L16+N16+P16+R16+T16+V16+X16+Z16+AB16+AD16+AF16+AH16+AJ16+AL16+AN16+AP16+AR16+AT16+AV16+AX16+AZ16+BB16+BD16+BF16+BH16+BJ16+BL16+BN16+BP16 -> 2 | BS16: 1.92 | BT16: =+BS16*D16 -> 303.36 | BU16: 115200 | BV16: =+BU16*BT16 -> 34947072
A18: GẠCH 80*80-BS | B18: LX8001 | C18: 17 | D18: =C18+BQ18-BR18 -> 17 | BQ18: =+E18+G18+I18+K18+M18+O18+Q18+S18+U18+W18+Y18+AA18+AC18+AE18+AG18+AI18+AK18+AM18+AO18+AQ18+AS18+AU18+AW18+AY18+BA18+BC18+BE18+BG18+BI18+BK18+BM18+BO18 -> 0 | BR18: =+F18+H18+J18+L18+N18+P18+R18+T18+V18+X18+Z18+AB18+AD18+AF18+AH18+AJ18+AL18+AN18+AP18+AR18+AT18+AV18+AX18+AZ18+BB18+BD18+BF18+BH18+BJ18+BL18+BN18+BP18 -> 0 | BS18: 1.92 | BT18: =+BS18*D18 -> 32.64 | BU18: 123800 | BV18: =+BU18*BT18 -> 4040832
B19: LX8002 | C19: 84 | D19: =C19+BQ19-BR19 -> 84 | BQ19: =+E19+G19+I19+K19+M19+O19+Q19+S19+U19+W19+Y19+AA19+AC19+AE19+AG19+AI19+AK19+AM19+AO19+AQ19+AS19+AU19+AW19+AY19+BA19+BC19+BE19+BG19+BI19+BK19+BM19+BO19 -> 0 | BR19: =+F19+H19+J19+L19+N19+P19+R19+T19+V19+X19+Z19+AB19+AD19+AF19+AH19+AJ19+AL19+AN19+AP19+AR19+AT19+AV19+AX19+AZ19+BB19+BD19+BF19+BH19+BJ19+BL19+BN19+BP19 -> 0 | BS19: 1.92 | BT19: =+BS19*D19 -> 161.28 | BU19: 123800 | BV19: =+BU19*BT19 -> 19966464
B20: LX8002 a2 | C20: 336 | D20: =C20+BQ20-BR20 -> 334 | P20: 2 | BQ20: =+E20+G20+I20+K20+M20+O20+Q20+S20+U20+W20+Y20+AA20+AC20+AE20+AG20+AI20+AK20+AM20+AO20+AQ20+AS20+AU20+AW20+AY20+BA20+BC20+BE20+BG20+BI20+BK20+BM20+BO20 -> 0 | BR20: =+F20+H20+J20+L20+N20+P20+R20+T20+V20+X20+Z20+AB20+AD20+AF20+AH20+AJ20+AL20+AN20+AP20+AR20+AT20+AV20+AX20+AZ20+BB20+BD20+BF20+BH20+BJ20+BL20+BN20+BP20 -> 2 | BS20: 1.92 | BT20: =+BS20*D20 -> 641.28 | BU20: 90000 | BV20: =+BU20*BT20 -> 57715200
B21: LX8003 | C21: 14 | D21: =C21+BQ21-BR21 -> 14 | BQ21: =+E21+G21+I21+K21+M21+O21+Q21+S21+U21+W21+Y21+AA21+AC21+AE21+AG21+AI21+AK21+AM21+AO21+AQ21+AS21+AU21+AW21+AY21+BA21+BC21+BE21+BG21+BI21+BK21+BM21+BO21 -> 0 | BR21: =+F21+H21+J21+L21+N21+P21+R21+T21+V21+X21+Z21+AB21+AD21+AF21+AH21+AJ21+AL21+AN21+AP21+AR21+AT21+AV21+AX21+AZ21+BB21+BD21+BF21+BH21+BJ21+BL21+BN21+BP21 -> 0 | BS21: 1.92 | BT21: =+BS21*D21 -> 26.88 | BU21: 123800 | BV21: =+BU21*BT21 -> 3327744
B22: LX8004 | C22: 14 | D22: =C22+BQ22-BR22 -> 14 | BQ22: =+E22+G22+I22+K22+M22+O22+Q22+S22+U22+W22+Y22+AA22+AC22+AE22+AG22+AI22+AK22+AM22+AO22+AQ22+AS22+AU22+AW22+AY22+BA22+BC22+BE22+BG22+BI22+BK22+BM22+BO22 -> 0 | BR22: =+F22+H22+J22+L22+N22+P22+R22+T22+V22+X22+Z22+AB22+AD22+AF22+AH22+AJ22+AL22+AN22+AP22+AR22+AT22+AV22+AX22+AZ22+BB22+BD22+BF22+BH22+BJ22+BL22+BN22+BP22 -> 0 | BS22: 1.92 | BT22: =+BS22*D22 -> 26.88 | BU22: 123800 | BV22: =+BU22*BT22 -> 3327744
B23: LX8005 | C23: 31 | D23: =C23+BQ23-BR23 -> 31 | BQ23: =+E23+G23+I23+K23+M23+O23+Q23+S23+U23+W23+Y23+AA23+AC23+AE23+AG23+AI23+AK23+AM23+AO23+AQ23+AS23+AU23+AW23+AY23+BA23+BC23+BE23+BG23+BI23+BK23+BM23+BO23 -> 0 | BR23: =+F23+H23+J23+L23+N23+P23+R23+T23+V23+X23+Z23+AB23+AD23+AF23+AH23+AJ23+AL23+AN23+AP23+AR23+AT23+AV23+AX23+AZ23+BB23+BD23+BF23+BH23+BJ23+BL23+BN23+BP23 -> 0 | BS23: 1.92 | BT23: =+BS23*D23 -> 59.52 | BU23: 123800 | BV23: =+BU23*BT23 -> 7368576
B24: LX8005- A2 | C24: 140 | D24: =C24+BQ24-BR24 -> 140 | BQ24: =+E24+G24+I24+K24+M24+O24+Q24+S24+U24+W24+Y24+AA24+AC24+AE24+AG24+AI24+AK24+AM24+AO24+AQ24+AS24+AU24+AW24+AY24+BA24+BC24+BE24+BG24+BI24+BK24+BM24+BO24 -> 0 | BR24: =+F24+H24+J24+L24+N24+P24+R24+T24+V24+X24+Z24+AB24+AD24+AF24+AH24+AJ24+AL24+AN24+AP24+AR24+AT24+AV24+AX24+AZ24+BB24+BD24+BF24+BH24+BJ24+BL24+BN24+BP24 -> 0 | BS24: 1.92 | BT24: =+BS24*D24 -> 268.8 | BU24: 104500 | BV24: =+BU24*BT24 -> 28089600
B25: LX8009 | C25: 19 | D25: =C25+BQ25-BR25 -> 19 | BQ25: =+E25+G25+I25+K25+M25+O25+Q25+S25+U25+W25+Y25+AA25+AC25+AE25+AG25+AI25+AK25+AM25+AO25+AQ25+AS25+AU25+AW25+AY25+BA25+BC25+BE25+BG25+BI25+BK25+BM25+BO25 -> 0 | BR25: =+F25+H25+J25+L25+N25+P25+R25+T25+V25+X25+Z25+AB25+AD25+AF25+AH25+AJ25+AL25+AN25+AP25+AR25+AT25+AV25+AX25+AZ25+BB25+BD25+BF25+BH25+BJ25+BL25+BN25+BP25 -> 0 | BS25: 1.92 | BT25: =+BS25*D25 -> 36.48 | BU25: 100000 | BV25: =+BU25*BT25 -> 3648000
B26: LX8009 - A2 | C26: 59 | D26: =C26+BQ26-BR26 -> 59 | BQ26: =+E26+G26+I26+K26+M26+O26+Q26+S26+U26+W26+Y26+AA26+AC26+AE26+AG26+AI26+AK26+AM26+AO26+AQ26+AS26+AU26+AW26+AY26+BA26+BC26+BE26+BG26+BI26+BK26+BM26+BO26 -> 0 | BR26: =+F26+H26+J26+L26+N26+P26+R26+T26+V26+X26+Z26+AB26+AD26+AF26+AH26+AJ26+AL26+AN26+AP26+AR26+AT26+AV26+AX26+AZ26+BB26+BD26+BF26+BH26+BJ26+BL26+BN26+BP26 -> 0 | BS26: 1.92 | BT26: =+BS26*D26 -> 113.28 | BU26: 90000 | BV26: =+BU26*BT26 -> 10195200
B27: LX8010 | C27: 9 | D27: =C27+BQ27-BR27 -> 9 | BQ27: =+E27+G27+I27+K27+M27+O27+Q27+S27+U27+W27+Y27+AA27+AC27+AE27+AG27+AI27+AK27+AM27+AO27+AQ27+AS27+AU27+AW27+AY27+BA27+BC27+BE27+BG27+BI27+BK27+BM27+BO27 -> 0 | BR27: =+F27+H27+J27+L27+N27+P27+R27+T27+V27+X27+Z27+AB27+AD27+AF27+AH27+AJ27+AL27+AN27+AP27+AR27+AT27+AV27+AX27+AZ27+BB27+BD27+BF27+BH27+BJ27+BL27+BN27+BP27 -> 0 | BS27: 1.92 | BT27: =+BS27*D27 -> 17.28 | BU27: 123800 | BV27: =+BU27*BT27 -> 2139264
B28: LX8012 | C28: 9 | D28: =C28+BQ28-BR28 -> 9 | BQ28: =+E28+G28+I28+K28+M28+O28+Q28+S28+U28+W28+Y28+AA28+AC28+AE28+AG28+AI28+AK28+AM28+AO28+AQ28+AS28+AU28+AW28+AY28+BA28+BC28+BE28+BG28+BI28+BK28+BM28+BO28 -> 0 | BR28: =+F28+H28+J28+L28+N28+P28+R28+T28+V28+X28+Z28+AB28+AD28+AF28+AH28+AJ28+AL28+AN28+AP28+AR28+AT28+AV28+AX28+AZ28+BB28+BD28+BF28+BH28+BJ28+BL28+BN28+BP28 -> 0 | BS28: 1.92 | BT28: =+BS28*D28 -> 17.28 | BU28: 123800 | BV28: =+BU28*BT28 -> 2139264
B29: LX8014 | C29: 14 | D29: =C29+BQ29-BR29 -> 14 | BQ29: =+E29+G29+I29+K29+M29+O29+Q29+S29+U29+W29+Y29+AA29+AC29+AE29+AG29+AI29+AK29+AM29+AO29+AQ29+AS29+AU29+AW29+AY29+BA29+BC29+BE29+BG29+BI29+BK29+BM29+BO29 -> 0 | BR29: =+F29+H29+J29+L29+N29+P29+R29+T29+V29+X29+Z29+AB29+AD29+AF29+AH29+AJ29+AL29+AN29+AP29+AR29+AT29+AV29+AX29+AZ29+BB29+BD29+BF29+BH29+BJ29+BL29+BN29+BP29 -> 0 | BS29: 1.92 | BT29: =+BS29*D29 -> 26.88 | BU29: 100000 | BV29: =+BU29*BT29 -> 2688000
B30: LX8014 -A2 | C30: 13 | D30: =C30+BQ30-BR30 -> 13 | BQ30: =+E30+G30+I30+K30+M30+O30+Q30+S30+U30+W30+Y30+AA30+AC30+AE30+AG30+AI30+AK30+AM30+AO30+AQ30+AS30+AU30+AW30+AY30+BA30+BC30+BE30+BG30+BI30+BK30+BM30+BO30 -> 0 | BR30: =+F30+H30+J30+L30+N30+P30+R30+T30+V30+X30+Z30+AB30+AD30+AF30+AH30+AJ30+AL30+AN30+AP30+AR30+AT30+AV30+AX30+AZ30+BB30+BD30+BF30+BH30+BJ30+BL30+BN30+BP30 -> 0 | BS30: 1.92 | BT30: =+BS30*D30 -> 24.96 | BU30: 65000 | BV30: =+BU30*BT30 -> 1622400
B31: LX8016 | C31: 37 | D31: =C31+BQ31-BR31 -> 37 | BQ31: =+E31+G31+I31+K31+M31+O31+Q31+S31+U31+W31+Y31+AA31+AC31+AE31+AG31+AI31+AK31+AM31+AO31+AQ31+AS31+AU31+AW31+AY31+BA31+BC31+BE31+BG31+BI31+BK31+BM31+BO31 -> 0 | BR31: =+F31+H31+J31+L31+N31+P31+R31+T31+V31+X31+Z31+AB31+AD31+AF31+AH31+AJ31+AL31+AN31+AP31+AR31+AT31+AV31+AX31+AZ31+BB31+BD31+BF31+BH31+BJ31+BL31+BN31+BP31 -> 0 | BS31: 1.92 | BT31: =+BS31*D31 -> 71.04 | BU31: 123800 | BV31: =+BU31*BT31 -> 8794752
B32: LX8016 - A2 | C32: 8 | D32: =C32+BQ32-BR32 -> 8 | BQ32: =+E32+G32+I32+K32+M32+O32+Q32+S32+U32+W32+Y32+AA32+AC32+AE32+AG32+AI32+AK32+AM32+AO32+AQ32+AS32+AU32+AW32+AY32+BA32+BC32+BE32+BG32+BI32+BK32+BM32+BO32 -> 0 | BR32: =+F32+H32+J32+L32+N32+P32+R32+T32+V32+X32+Z32+AB32+AD32+AF32+AH32+AJ32+AL32+AN32+AP32+AR32+AT32+AV32+AX32+AZ32+BB32+BD32+BF32+BH32+BJ32+BL32+BN32+BP32 -> 0 | BS32: 1.92 | BT32: =+BS32*D32 -> 15.36 | BU32: 104500 | BV32: =+BU32*BT32 -> 1605120
... B34: LX8017 a2 | C34: 37 | D34: =C34+BQ34-BR34 -> 37 | BQ34: =+E34+G34+I34+K34+M34+O34+Q34+S34+U34+W34+Y34+AA34+AC34+AE34+AG34+AI34+AK34+AM34+AO34+AQ34+AS34+AU34+AW34+AY34+BA34+BC34+BE34+BG34+BI34+BK34+BM34+BO34 -> 0 | BR34: =+F34+H34+J34+L34+N34+P34+R34+T34+V34+X34+Z34+AB34+AD34+AF34+AH34+AJ34+AL34+AN34+AP34+AR34+AT34+AV34+AX34+AZ34+BB34+BD34+BF34+BH34+BJ34+BL34+BN34+BP34 -> 0 | BS34: 1.92 | BT34: =+BS34*D34 -> 71.04 | BU34: 90000 | BV34: =+BU34*BT34 -> 6393600
C35: 0 | D35: =C35+BQ35-BR35 -> 0 | BQ35: =+E35+G35+I35+K35+M35+O35+Q35+S35+U35+W35+Y35+AA35+AC35+AE35+AG35+AI35+AK35+AM35+AO35+AQ35+AS35+AU35+AW35+AY35+BA35+BC35+BE35+BG35+BI35+BK35+BM35+BO35 -> 0 | BR35: =+F35+H35+J35+L35+N35+P35+R35+T35+V35+X35+Z35+AB35+AD35+AF35+AH35+AJ35+AL35+AN35+AP35+AR35+AT35+AV35+AX35+AZ35+BB35+BD35+BF35+BH35+BJ35+BL35+BN35+BP35 -> 0 | BT35: =+BS35*D35 -> 0 | BV35: =+BU35*BT35 -> 0
A36: 80*80 ECO | B36: LP18101 | C36: 194.033 | D36: =C36+BQ36-BR36 -> 194.033 | BQ36: =+E36+G36+I36+K36+M36+O36+Q36+S36+U36+W36+Y36+AA36+AC36+AE36+AG36+AI36+AK36+AM36+AO36+AQ36+AS36+AU36+AW36+AY36+BA36+BC36+BE36+BG36+BI36+BK36+BM36+BO36 -> 0 | BR36: =+F36+H36+J36+L36+N36+P36+R36+T36+V36+X36+Z36+AB36+AD36+AF36+AH36+AJ36+AL36+AN36+AP36+AR36+AT36+AV36+AX36+AZ36+BB36+BD36+BF36+BH36+BJ36+BL36+BN36+BP36 -> 0 | BS36: 1.92 | BT36: =+BS36*D36 -> 372.54336 | BU36: 115810 | BV36: =+BU36*BT36 -> 43144247
B37: LP18101 A2 | C37: 0 | D37: =C37+BQ37-BR37 -> 0 | BQ37: =+E37+G37+I37+K37+M37+O37+Q37+S37+U37+W37+Y37+AA37+AC37+AE37+AG37+AI37+AK37+AM37+AO37+AQ37+AS37+AU37+AW37+AY37+BA37+BC37+BE37+BG37+BI37+BK37+BM37+BO37 -> 0 | BR37: =+F37+H37+J37+L37+N37+P37+R37+T37+V37+X37+Z37+AB37+AD37+AF37+AH37+AJ37+AL37+AN37+AP37+AR37+AT37+AV37+AX37+AZ37+BB37+BD37+BF37+BH37+BJ37+BL37+BN37+BP37 -> 0 | BS37: 1.92 | BT37: =+BS37*D37 -> 0 | BU37: 95210 | BV37: =+BU37*BT37 -> 0
B38: LP18102 | C38: 105 | D38: =C38+BQ38-BR38 -> 105 | BQ38: =+E38+G38+I38+K38+M38+O38+Q38+S38+U38+W38+Y38+AA38+AC38+AE38+AG38+AI38+AK38+AM38+AO38+AQ38+AS38+AU38+AW38+AY38+BA38+BC38+BE38+BG38+BI38+BK38+BM38+BO38 -> 0 | BR38: =+F38+H38+J38+L38+N38+P38+R38+T38+V38+X38+Z38+AB38+AD38+AF38+AH38+AJ38+AL38+AN38+AP38+AR38+AT38+AV38+AX38+AZ38+BB38+BD38+BF38+BH38+BJ38+BL38+BN38+BP38 -> 0 | BS38: 1.92 | BT38: =+BS38*D38 -> 201.6 | BU38: 115810 | BV38: =+BU38*BT38 -> 23347296
B39: LP18102 A2 | C39: 20 | D39: =C39+BQ39-BR39 -> 20 | BQ39: =+E39+G39+I39+K39+M39+O39+Q39+S39+U39+W39+Y39+AA39+AC39+AE39+AG39+AI39+AK39+AM39+AO39+AQ39+AS39+AU39+AW39+AY39+BA39+BC39+BE39+BG39+BI39+BK39+BM39+BO39 -> 0 | BR39: =+F39+H39+J39+L39+N39+P39+R39+T39+V39+X39+Z39+AB39+AD39+AF39+AH39+AJ39+AL39+AN39+AP39+AR39+AT39+AV39+AX39+AZ39+BB39+BD39+BF39+BH39+BJ39+BL39+BN39+BP39 -> 0 | BS39: 1.92 | BT39: =+BS39*D39 -> 38.4 | BU39: 95210 | BV39: =+BU39*BT39 -> 3656064
B40: LP18103 | C40: 186 | D40: =C40+BQ40-BR40 -> 186 | BQ40: =+E40+G40+I40+K40+M40+O40+Q40+S40+U40+W40+Y40+AA40+AC40+AE40+AG40+AI40+AK40+AM40+AO40+AQ40+AS40+AU40+AW40+AY40+BA40+BC40+BE40+BG40+BI40+BK40+BM40+BO40 -> 0 | BR40: =+F40+H40+J40+L40+N40+P40+R40+T40+V40+X40+Z40+AB40+AD40+AF40+AH40+AJ40+AL40+AN40+AP40+AR40+AT40+AV40+AX40+AZ40+BB40+BD40+BF40+BH40+BJ40+BL40+BN40+BP40 -> 0 | BS40: 1.92 | BT40: =+BS40*D40 -> 357.12 | BU40: 115810 | BV40: =+BU40*BT40 -> 41358067
B41: LP18103 A2 | C41: 0 | D41: =C41+BQ41-BR41 -> 0 | BQ41: =+E41+G41+I41+K41+M41+O41+Q41+S41+U41+W41+Y41+AA41+AC41+AE41+AG41+AI41+AK41+AM41+AO41+AQ41+AS41+AU41+AW41+AY41+BA41+BC41+BE41+BG41+BI41+BK41+BM41+BO41 -> 0 | BR41: =+F41+H41+J41+L41+N41+P41+R41+T41+V41+X41+Z41+AB41+AD41+AF41+AH41+AJ41+AL41+AN41+AP41+AR41+AT41+AV41+AX41+AZ41+BB41+BD41+BF41+BH41+BJ41+BL41+BN41+BP41 -> 0 | BS41: 1.92 | BT41: =+BS41*D41 -> 0 | BU41: 95210 | BV41: =+BU41*BT41 -> 0
B42: LP18104 | C42: 147 | D42: =C42+BQ42-BR42 -> 86 | H42: =55+6 -> 61 | BQ42: =+E42+G42+I42+K42+M42+O42+Q42+S42+U42+W42+Y42+AA42+AC42+AE42+AG42+AI42+AK42+AM42+AO42+AQ42+AS42+AU42+AW42+AY42+BA42+BC42+BE42+BG42+BI42+BK42+BM42+BO42 -> 0 | BR42: =+F42+H42+J42+L42+N42+P42+R42+T42+V42+X42+Z42+AB42+AD42+AF42+AH42+AJ42+AL42+AN42+AP42+AR42+AT42+AV42+AX42+AZ42+BB42+BD42+BF42+BH42+BJ42+BL42+BN42+BP42 -> 61 | BS42: 1.92 | BT42: =+BS42*D42 -> 165.12 | BU42: 115810 | BV42: =+BU42*BT42 -> 19122547
...

Sheet NISE
A1: KÍCH THƯỚC | B1: MÃ SP | C1: TỒN CK 30.6.2026 | D1: TỒN HIỆN TẠI T7.2026 | E1: 1 | G1: =1+E1 -> 2 | I1: =1+G1 -> 3 | K1: =1+I1 -> 4 | M1: 5 | O1: =1+M1 -> 6 | Q1: =1+O1 -> 7 | S1: =1+Q1 -> 8 | U1: =1+S1 -> 9 | W1: =1+U1 -> 10 | Y1: =1+W1 -> 11 | AA1: =1+Y1 -> 12 | AC1: =1+AA1 -> 13 | AE1: =1+AC1 -> 14 | AG1: =1+AE1 -> 15 | AI1: =1+AG1 -> 16 | AK1: =1+AI1 -> 17 | AM1: =1+AK1 -> 18 | AO1: =1+AM1 -> 19 | AQ1: =1+AO1 -> 20 | AS1: =1+AQ1 -> 21 | AU1: =1+AS1 -> 22 | AW1: =1+AU1 -> 23 | AY1: =1+AW1 -> 24 | BA1: =1+AY1 -> 25 | BC1: =1+BA1 -> 26 | BE1: =1+BC1 -> 27 | BG1: =1+BE1 -> 28 | BI1: =1+BG1 -> 29 | BK1: =1+BI1 -> 30 | BM1: =1+BK1 -> 31 | BO1: Thiếu k nguyên nhân | BQ1: TỔNG | BS1: M2/H | BT1: QUY M2 | BU1: ĐƠN GIÁ/m | BV1: THÀNH TIỀN
A2: TỔNG CỘNG | C2: =SUM(C4:C147) -> 14358.084 | D2: =SUM(D4:D147) -> 13285.584 | E2: N | F2: X | G2: N | H2: X | I2: N | J2: X | K2: N | L2: X | M2: N | N2: X | O2: N | P2: X | Q2: N | R2: X | S2: N | T2: X | U2: N | V2: X | W2: N | X2: X | Y2: N | Z2: X | AA2: N | AB2: X | AC2: N | AD2: X | AE2: N | AF2: X | AG2: N | AH2: X | AI2: N | AJ2: X | AK2: N | AL2: X | AM2: N | AN2: X | AO2: N | AP2: X | AQ2: N | AR2: X | AS2: N | AT2: X | AU2: N | AV2: X | AW2: N | AX2: X | AY2: N | AZ2: X | BA2: N | BB2: X | BC2: N | BD2: X | BE2: N | BF2: X | BG2: N | BH2: X | BI2: N | BJ2: X | BK2: N | BL2: X | BM2: N | BN2: X | BO2: N | BP2: X | BQ2: N | BR2: X | BS2: 340.82 | BT2: =SUM(BT5:BT147) -> 21685.928 | BV2: =SUM(BV5:BV147) -> 2.1246736e+09
E3: =SUM(E4:E267) -> 0 | F3: =SUM(F4:F267) -> 120 | G3: =SUM(G4:G267) -> 0 | H3: =SUM(H4:H267) -> 62 | I3: =SUM(I4:I267) -> 344 | J3: =SUM(J4:J267) -> 129 | K3: =SUM(K4:K267) -> 2 | L3: =SUM(L4:L267) -> 17 | ... Q3: =SUM(Q4:Q267) -> 0 | R3: =SUM(R4:R144) -> 207 | S3: =SUM(S4:S267) -> 5 | T3: =SUM(T4:T267) -> 72 | U3: =SUM(U4:U267) -> 1 | V3: =SUM(V4:V267) -> 72 | W3: =SUM(W4:W267) -> 13 | X3: =SUM(X4:X267) -> 40 | Y3: =SUM(Y4:Y267) -> 0 | Z3: =SUM(Z4:Z267) -> 117 | ... BP3: =SUM(BP4:BP267) -> 30 | BQ3: =+E3+G3+I3+K3+M3+O3+Q3+S3+U3+W3+Y3+AA3+AC3+AE3+AG3+AI3+AK3+AM3+AO3+AQ3+AS3+AU3+AW3+AY3+BA3+BC3+BE3+BG3+BI3+BK3+BM3+BO3 -> 1915 | BR3: =+F3+H3+J3+L3+N3+P3+R3+T3+V3+X3+Z3+AB3+AD3+AF3+AH3+AJ3+AL3+AN3+AP3+AR3+AT3+AV3+AX3+AZ3+BB3+BD3+BF3+BH3+BJ3+BL3+BN3+BP3 -> 2987.5
BQ4: =+E4+G4+I4+K4+M4+O4+Q4+S4+U4+W4+Y4+AA4+AC4+AE4+AG4+AI4+AK4+AM4+AO4+AQ4+AS4+AU4+AW4+AY4+BA4+BC4+BE4+BG4+BI4+BK4+BM4+BO4 -> 0 | BR4: =+F4+H4+J4+L4+N4+P4+R4+T4+V4+X4+Z4+AB4+AD4+AF4+AH4+AJ4+AL4+AN4+AP4+AR4+AT4+AV4+AX4+AZ4+BB4+BD4+BF4+BH4+BJ4+BL4+BN4+BP4 -> 0
A5: 30*60 BÁN SỨ | B5: 036-6002 Nhạt | C5: 250 | D5: =+C5+BQ5-BR5 -> 250 | BQ5: =+E5+G5+I5+K5+M5+O5+Q5+S5+U5+W5+Y5+AA5+AC5+AE5+AG5+AI5+AK5+AM5+AO5+AQ5+AS5+AU5+AW5+AY5+BA5+BC5+BE5+BG5+BI5+BK5+BM5+BO5 -> 0 | BR5: =+F5+H5+J5+L5+N5+P5+R5+T5+V5+X5+Z5+AB5+AD5+AF5+AH5+AJ5+AL5+AN5+AP5+AR5+AT5+AV5+AX5+AZ5+BB5+BD5+BF5+BH5+BJ5+BL5+BN5+BP5 -> 0 | BS5: 1.44 | BT5: =+BS5*D5 -> 360 | BU5: 76500 | BV5: =+BU5*BT5 -> 27540000
B6: 036-6003 nhạt | C6: 68 | D6: =+C6+BQ6-BR6 -> 68 | BQ6: =+E6+G6+I6+K6+M6+O6+Q6+S6+U6+W6+Y6+AA6+AC6+AE6+AG6+AI6+AK6+AM6+AO6+AQ6+AS6+AU6+AW6+AY6+BA6+BC6+BE6+BG6+BI6+BK6+BM6+BO6 -> 0 | BR6: =+F6+H6+J6+L6+N6+P6+R6+T6+V6+X6+Z6+AB6+AD6+AF6+AH6+AJ6+AL6+AN6+AP6+AR6+AT6+AV6+AX6+AZ6+BB6+BD6+BF6+BH6+BJ6+BL6+BN6+BP6 -> 0 | BS6: 1.44 | BT6: =+BS6*D6 -> 97.92 | BU6: 95250 | BV6: =+BU6*BT6 -> 9326880
B7: 036-601-kem vàng | C7: 16 | D7: =+C7+BQ7-BR7 -> 16 | BQ7: =+E7+G7+I7+K7+M7+O7+Q7+S7+U7+W7+Y7+AA7+AC7+AE7+AG7+AI7+AK7+AM7+AO7+AQ7+AS7+AU7+AW7+AY7+BA7+BC7+BE7+BG7+BI7+BK7+BM7+BO7 -> 0 | BR7: =+F7+H7+J7+L7+N7+P7+R7+T7+V7+X7+Z7+AB7+AD7+AF7+AH7+AJ7+AL7+AN7+AP7+AR7+AT7+AV7+AX7+AZ7+BB7+BD7+BF7+BH7+BJ7+BL7+BN7+BP7 -> 0 | BS7: 1.44 | BT7: =+BS7*D7 -> 23.04 | BU7: 76500 | BV7: =+BU7*BT7 -> 1762560
C8: 0 | D8: =+C8+BQ8-BR8 -> 0 | BQ8: =+E8+G8+I8+K8+M8+O8+Q8+S8+U8+W8+Y8+AA8+AC8+AE8+AG8+AI8+AK8+AM8+AO8+AQ8+AS8+AU8+AW8+AY8+BA8+BC8+BE8+BG8+BI8+BK8+BM8+BO8 -> 0 | BR8: =+F8+H8+J8+L8+N8+P8+R8+T8+V8+X8+Z8+AB8+AD8+AF8+AH8+AJ8+AL8+AN8+AP8+AR8+AT8+AV8+AX8+AZ8+BB8+BD8+BF8+BH8+BJ8+BL8+BN8+BP8 -> 0 | BT8: =+BS8*D8 -> 0 | BV8: =+BU8*BT8 -> 0
C9: 0 | D9: =+C9+BQ9-BR9 -> 0 | BQ9: =+E9+G9+I9+K9+M9+O9+Q9+S9+U9+W9+Y9+AA9+AC9+AE9+AG9+AI9+AK9+AM9+AO9+AQ9+AS9+AU9+AW9+AY9+BA9+BC9+BE9+BG9+BI9+BK9+BM9+BO9 -> 0 | BR9: =+F9+H9+J9+L9+N9+P9+R9+T9+V9+X9+Z9+AB9+AD9+AF9+AH9+AJ9+AL9+AN9+AP9+AR9+AT9+AV9+AX9+AZ9+BB9+BD9+BF9+BH9+BJ9+BL9+BN9+BP9 -> 0 | BT9: =+BS9*D9 -> 0 | BV9: =+BU9*BT9 -> 0
A10: 40*80 BỘ BS | B10: 48-601-Kem vàng | C10: 0 | D10: =+C10+BQ10-BR10 -> 0 | BQ10: =+E10+G10+I10+K10+M10+O10+Q10+S10+U10+W10+Y10+AA10+AC10+AE10+AG10+AI10+AK10+AM10+AO10+AQ10+AS10+AU10+AW10+AY10+BA10+BC10+BE10+BG10+BI10+BK10+BM10+BO10 -> 0 | BR10: =+F10+H10+J10+L10+N10+P10+R10+T10+V10+X10+Z10+AB10+AD10+AF10+AH10+AJ10+AL10+AN10+AP10+AR10+AT10+AV10+AX10+AZ10+BB10+BD10+BF10+BH10+BJ10+BL10+BN10+BP10 -> 0 | BS10: 1.92 | BT10: =+BS10*D10 -> 0 | BU10: 98000 | BV10: =+BU10*BT10 -> 0
B11: 48-6000- Trắng tinh-53(30.12.23) | C11: 6 | D11: =+C11+BQ11-BR11 -> 6 | BQ11: =+E11+G11+I11+K11+M11+O11+Q11+S11+U11+W11+Y11+AA11+AC11+AE11+AG11+AI11+AK11+AM11+AO11+AQ11+AS11+AU11+AW11+AY11+BA11+BC11+BE11+BG11+BI11+BK11+BM11+BO11 -> 0 | BR11: =+F11+H11+J11+L11+N11+P11+R11+T11+V11+X11+Z11+AB11+AD11+AF11+AH11+AJ11+AL11+AN11+AP11+AR11+AT11+AV11+AX11+AZ11+BB11+BD11+BF11+BH11+BJ11+BL11+BN11+BP11 -> 0 | BS11: 1.92 | BT11: =+BS11*D11 -> 11.52 | BU11: 103000 | BV11: =+BU11*BT11 -> 1186560
C12: 0 | D12: =+C12+BQ12-BR12 -> 0 | BQ12: =+E12+G12+I12+K12+M12+O12+Q12+S12+U12+W12+Y12+AA12+AC12+AE12+AG12+AI12+AK12+AM12+AO12+AQ12+AS12+AU12+AW12+AY12+BA12+BC12+BE12+BG12+BI12+BK12+BM12+BO12 -> 0 | BR12: =+F12+H12+J12+L12+N12+P12+R12+T12+V12+X12+Z12+AB12+AD12+AF12+AH12+AJ12+AL12+AN12+AP12+AR12+AT12+AV12+AX12+AZ12+BB12+BD12+BF12+BH12+BJ12+BL12+BN12+BP12 -> 0 | BS12: 1.92 | BT12: =+BS12*D12 -> 0 | BV12: =+BU12*BT12 -> 0
B13: 48-6001-Nhạt | C13: 70 | D13: =+C13+BQ13-BR13 -> 52 | T13: 12 | AX13: 6 | BQ13: =+E13+G13+I13+K13+M13+O13+Q13+S13+U13+W13+Y13+AA13+AC13+AE13+AG13+AI13+AK13+AM13+AO13+AQ13+AS13+AU13+AW13+AY13+BA13+BC13+BE13+BG13+BI13+BK13+BM13+BO13 -> 0 | BR13: =+F13+H13+J13+L13+N13+P13+R13+T13+V13+X13+Z13+AB13+AD13+AF13+AH13+AJ13+AL13+AN13+AP13+AR13+AT13+AV13+AX13+AZ13+BB13+BD13+BF13+BH13+BJ13+BL13+BN13+BP13 -> 18 | BS13: 1.92 | BT13: =+BS13*D13 -> 99.84 | BU13: 98000 | BV13: =+BU13*BT13 -> 9784320
B14: 48-6001-Đậm | C14: 61.67 | D14: =+C14+BQ14-BR14 -> 55.67 | AX14: 6 | BQ14: =+E14+G14+I14+K14+M14+O14+Q14+S14+U14+W14+Y14+AA14+AC14+AE14+AG14+AI14+AK14+AM14+AO14+AQ14+AS14+AU14+AW14+AY14+BA14+BC14+BE14+BG14+BI14+BK14+BM14+BO14 -> 0 | BR14: =+F14+H14+J14+L14+N14+P14+R14+T14+V14+X14+Z14+AB14+AD14+AF14+AH14+AJ14+AL14+AN14+AP14+AR14+AT14+AV14+AX14+AZ14+BB14+BD14+BF14+BH14+BJ14+BL14+BN14+BP14 -> 6 | BS14: 1.92 | BT14: =+BS14*D14 -> 106.8864 | BU14: 103000 | BV14: =+BU14*BT14 -> 11009299
B15: 48-6001-Điểm | C15: 11 | D15: =+C15+BQ15-BR15 -> 9 | AX15: 2 | BQ15: =+E15+G15+I15+K15+M15+O15+Q15+S15+U15+W15+Y15+AA15+AC15+AE15+AG15+AI15+AK15+AM15+AO15+AQ15+AS15+AU15+AW15+AY15+BA15+BC15+BE15+BG15+BI15+BK15+BM15+BO15 -> 0 | BR15: =+F15+H15+J15+L15+N15+P15+R15+T15+V15+X15+Z15+AB15+AD15+AF15+AH15+AJ15+AL15+AN15+AP15+AR15+AT15+AV15+AX15+AZ15+BB15+BD15+BF15+BH15+BJ15+BL15+BN15+BP15 -> 2 | BS15: 1.92 | BT15: =+BS15*D15 -> 17.28 | BU15: 103000 | BV15: =+BU15*BT15 -> 1779840
C16: 0 | D16: =+C16+BQ16-BR16 -> 0 | BQ16: =+E16+G16+I16+K16+M16+O16+Q16+S16+U16+W16+Y16+AA16+AC16+AE16+AG16+AI16+AK16+AM16+AO16+AQ16+AS16+AU16+AW16+AY16+BA16+BC16+BE16+BG16+BI16+BK16+BM16+BO16 -> 0 | BR16: =+F16+H16+J16+L16+N16+P16+R16+T16+V16+X16+Z16+AB16+AD16+AF16+AH16+AJ16+AL16+AN16+AP16+AR16+AT16+AV16+AX16+AZ16+BB16+BD16+BF16+BH16+BJ16+BL16+BN16+BP16 -> 0 | BT16: =+BS16*D16 -> 0 | BV16: =+BU16*BT16 -> 0
B17: 48-6002-Khói | C17: 144 | D17: =+C17+BQ17-BR17 -> 131 | T17: 13 | BQ17: =+E17+G17+I17+K17+M17+O17+Q17+S17+U17+W17+Y17+AA17+AC17+AE17+AG17+AI17+AK17+AM17+AO17+AQ17+AS17+AU17+AW17+AY17+BA17+BC17+BE17+BG17+BI17+BK17+BM17+BO17 -> 0 | BR17: =+F17+H17+J17+L17+N17+P17+R17+T17+V17+X17+Z17+AB17+AD17+AF17+AH17+AJ17+AL17+AN17+AP17+AR17+AT17+AV17+AX17+AZ17+BB17+BD17+BF17+BH17+BJ17+BL17+BN17+BP17 -> 13 | BS17: 1.92 | BT17: =+BS17*D17 -> 251.52 | BU17: 98000 | BV17: =+BU17*BT17 -> 24648960
B18: 48-6002-Điểm | C18: 6 | D18: =+C18+BQ18-BR18 -> 6 | BQ18: =+E18+G18+I18+K18+M18+O18+Q18+S18+U18+W18+Y18+AA18+AC18+AE18+AG18+AI18+AK18+AM18+AO18+AQ18+AS18+AU18+AW18+AY18+BA18+BC18+BE18+BG18+BI18+BK18+BM18+BO18 -> 0 | BR18: =+F18+H18+J18+L18+N18+P18+R18+T18+V18+X18+Z18+AB18+AD18+AF18+AH18+AJ18+AL18+AN18+AP18+AR18+AT18+AV18+AX18+AZ18+BB18+BD18+BF18+BH18+BJ18+BL18+BN18+BP18 -> 0 | BS18: 1.92 | BT18: =+BS18*D18 -> 11.52 | BU18: 103000 | BV18: =+BU18*BT18 -> 1186560
C19: 0 | D19: =+C19+BQ19-BR19 -> 0 | BQ19: =+E19+G19+I19+K19+M19+O19+Q19+S19+U19+W19+Y19+AA19+AC19+AE19+AG19+AI19+AK19+AM19+AO19+AQ19+AS19+AU19+AW19+AY19+BA19+BC19+BE19+BG19+BI19+BK19+BM19+BO19 -> 0 | BR19: =+F19+H19+J19+L19+N19+P19+R19+T19+V19+X19+Z19+AB19+AD19+AF19+AH19+AJ19+AL19+AN19+AP19+AR19+AT19+AV19+AX19+AZ19+BB19+BD19+BF19+BH19+BJ19+BL19+BN19+BP19 -> 0 | BS19: 1.92 | BT19: =+BS19*D19 -> 0 | BV19: =+BU19*BT19 -> 0
B20: 48-6003-Vân | C20: 90 | D20: =+C20+BQ20-BR20 -> 90 | BQ20: =+E20+G20+I20+K20+M20+O20+Q20+S20+U20+W20+Y20+AA20+AC20+AE20+AG20+AI20+AK20+AM20+AO20+AQ20+AS20+AU20+AW20+AY20+BA20+BC20+BE20+BG20+BI20+BK20+BM20+BO20 -> 0 | BR20: =+F20+H20+J20+L20+N20+P20+R20+T20+V20+X20+Z20+AB20+AD20+AF20+AH20+AJ20+AL20+AN20+AP20+AR20+AT20+AV20+AX20+AZ20+BB20+BD20+BF20+BH20+BJ20+BL20+BN20+BP20 -> 0 | BS20: 1.92 | BT20: =+BS20*D20 -> 172.8 | BU20: 98000 | BV20: =+BU20*BT20 -> 16934400
B21: 48-6003-Điểm | C21: 19 | D21: =+C21+BQ21-BR21 -> 19 | BQ21: =+E21+G21+I21+K21+M21+O21+Q21+S21+U21+W21+Y21+AA21+AC21+AE21+AG21+AI21+AK21+AM21+AO21+AQ21+AS21+AU21+AW21+AY21+BA21+BC21+BE21+BG21+BI21+BK21+BM21+BO21 -> 0 | BR21: =+F21+H21+J21+L21+N21+P21+R21+T21+V21+X21+Z21+AB21+AD21+AF21+AH21+AJ21+AL21+AN21+AP21+AR21+AT21+AV21+AX21+AZ21+BB21+BD21+BF21+BH21+BJ21+BL21+BN21+BP21 -> 0 | BS21: 1.92 | BT21: =+BS21*D21 -> 36.48 | BU21: 103000 | BV21: =+BU21*BT21 -> 3757440
C22: 0 | D22: =+C22+BQ22-BR22 -> 0 | BQ22: =+E22+G22+I22+K22+M22+O22+Q22+S22+U22+W22+Y22+AA22+AC22+AE22+AG22+AI22+AK22+AM22+AO22+AQ22+AS22+AU22+AW22+AY22+BA22+BC22+BE22+BG22+BI22+BK22+BM22+BO22 -> 0 | BR22: =+F22+H22+J22+L22+N22+P22+R22+T22+V22+X22+Z22+AB22+AD22+AF22+AH22+AJ22+AL22+AN22+AP22+AR22+AT22+AV22+AX22+AZ22+BB22+BD22+BF22+BH22+BJ22+BL22+BN22+BP22 -> 0 | BT22: =+BS22*D22 -> 0 | BV22: =+BU22*BT22 -> 0
B23: 48-6007-Nhạt | C23: 168 | D23: =+C23+BQ23-BR23 -> 76 | X23: 35 | AF23: 22 | AH23: 5 | AJ23: 4 | AL23: 1 | AP23: 6 | BE23: 1 | BH23: 20 | BQ23: =+E23+G23+I23+K23+M23+O23+Q23+S23+U23+W23+Y23+AA23+AC23+AE23+AG23+AI23+AK23+AM23+AO23+AQ23+AS23+AU23+AW23+AY23+BA23+BC23+BE23+BG23+BI23+BK23+BM23+BO23 -> 1 | BR23: =+F23+H23+J23+L23+N23+P23+R23+T23+V23+X23+Z23+AB23+AD23+AF23+AH23+AJ23+AL23+AN23+AP23+AR23+AT23+AV23+AX23+AZ23+BB23+BD23+BF23+BH23+BJ23+BL23+BN23+BP23 -> 93 | BS23: 1.92 | BT23: =+BS23*D23 -> 145.92 | BU23: 98000 | BV23: =+BU23*BT23 -> 14300160
B24: 48-6007-Đậm | C24: 102.17 | D24: =+C24+BQ24-BR24 -> 79.17 | J24: 1 | P24: 1 | AF24: 15 | AH24: 3 | AP24: 4 | BE24: 1 | BQ24: =+E24+G24+I24+K24+M24+O24+Q24+S24+U24+W24+Y24+AA24+AC24+AE24+AG24+AI24+AK24+AM24+AO24+AQ24+AS24+AU24+AW24+AY24+BA24+BC24+BE24+BG24+BI24+BK24+BM24+BO24 -> 1 | BR24: =+F24+H24+J24+L24+N24+P24+R24+T24+V24+X24+Z24+AB24+AD24+AF24+AH24+AJ24+AL24+AN24+AP24+AR24+AT24+AV24+AX24+AZ24+BB24+BD24+BF24+BH24+BJ24+BL24+BN24+BP24 -> 24 | BS24: 1.92 | BT24: =+BS24*D24 -> 152.0064 | BU24: 103000 | BV24: =+BU24*BT24 -> 15656659
B25: 48-6007-Điểm | C25: 37.66 | D25: =+C25+BQ25-BR25 -> 35.66 | AH25: 2 | BQ25: =+E25+G25+I25+K25+M25+O25+Q25+S25+U25+W25+Y25+AA25+AC25+AE25+AG25+AI25+AK25+AM25+AO25+AQ25+AS25+AU25+AW25+AY25+BA25+BC25+BE25+BG25+BI25+BK25+BM25+BO25 -> 0 | BR25: =+F25+H25+J25+L25+N25+P25+R25+T25+V25+X25+Z25+AB25+AD25+AF25+AH25+AJ25+AL25+AN25+AP25+AR25+AT25+AV25+AX25+AZ25+BB25+BD25+BF25+BH25+BJ25+BL25+BN25+BP25 -> 2 | BS25: 1.92 | BT25: =+BS25*D25 -> 68.4672 | BU25: 103000 | BV25: =+BU25*BT25 -> 7052121.6
C26: 0 | D26: =+C26+BQ26-BR26 -> 0 | BQ26: =+E26+G26+I26+K26+M26+O26+Q26+S26+U26+W26+Y26+AA26+AC26+AE26+AG26+AI26+AK26+AM26+AO26+AQ26+AS26+AU26+AW26+AY26+BA26+BC26+BE26+BG26+BI26+BK26+BM26+BO26 -> 0 | BR26: =+F26+H26+J26+L26+N26+P26+R26+T26+V26+X26+Z26+AB26+AD26+AF26+AH26+AJ26+AL26+AN26+AP26+AR26+AT26+AV26+AX26+AZ26+BB26+BD26+BF26+BH26+BJ26+BL26+BN26+BP26 -> 0 | BT26: =+BS26*D26 -> 0 | BV26: =+BU26*BT26 -> 0
B27: 48-5004-Nhạt-56(18.11.22) | C27: 68 | D27: =+C27+BQ27-BR27 -> 65 | BH27: 3 | BQ27: =+E27+G27+I27+K27+M27+O27+Q27+S27+U27+W27+Y27+AA27+AC27+AE27+AG27+AI27+AK27+AM27+AO27+AQ27+AS27+AU27+AW27+AY27+BA27+BC27+BE27+BG27+BI27+BK27+BM27+BO27 -> 0 | BR27: =+F27+H27+J27+L27+N27+P27+R27+T27+V27+X27+Z27+AB27+AD27+AF27+AH27+AJ27+AL27+AN27+AP27+AR27+AT27+AV27+AX27+AZ27+BB27+BD27+BF27+BH27+BJ27+BL27+BN27+BP27 -> 3 | BS27: 1.92 | BT27: =+BS27*D27 -> 124.8 | BU27: 98000 | BV27: =+BU27*BT27 -> 12230400
B28: 48-5004-nhạt đ53(14.5.25) | C28: 5 | D28: =+C28+BQ28-BR28 -> 5 | BQ28: =+E28+G28+I28+K28+M28+O28+Q28+S28+U28+W28+Y28+AA28+AC28+AE28+AG28+AI28+AK28+AM28+AO28+AQ28+AS28+AU28+AW28+AY28+BA28+BC28+BE28+BG28+BI28+BK28+BM28+BO28 -> 0 | BR28: =+F28+H28+J28+L28+N28+P28+R28+T28+V28+X28+Z28+AB28+AD28+AF28+AH28+AJ28+AL28+AN28+AP28+AR28+AT28+AV28+AX28+AZ28+BB28+BD28+BF28+BH28+BJ28+BL28+BN28+BP28 -> 0 | BT28: =+BS28*D28 -> 0 | BV28: =+BU28*BT28 -> 0
B29: 48-5004-Đậm | C29: 99 | D29: =+C29+BQ29-BR29 -> 85 | V29: 11 | BJ29: 3 | BQ29: =+E29+G29+I29+K29+M29+O29+Q29+S29+U29+W29+Y29+AA29+AC29+AE29+AG29+AI29+AK29+AM29+AO29+AQ29+AS29+AU29+AW29+AY29+BA29+BC29+BE29+BG29+BI29+BK29+BM29+BO29 -> 0 | BR29: =+F29+H29+J29+L29+N29+P29+R29+T29+V29+X29+Z29+AB29+AD29+AF29+AH29+AJ29+AL29+AN29+AP29+AR29+AT29+AV29+AX29+AZ29+BB29+BD29+BF29+BH29+BJ29+BL29+BN29+BP29 -> 14 | BS29: 1.92 | BT29: =+BS29*D29 -> 163.2 | BU29: 103000 | BV29: =+BU29*BT29 -> 16809600
B30: 48-5004-Đậm A2 | C30: 6 | D30: =+C30+BQ30-BR30 -> 6 | BQ30: =+E30+G30+I30+K30+M30+O30+Q30+S30+U30+W30+Y30+AA30+AC30+AE30+AG30+AI30+AK30+AM30+AO30+AQ30+AS30+AU30+AW30+AY30+BA30+BC30+BE30+BG30+BI30+BK30+BM30+BO30 -> 0 | BR30: =+F30+H30+J30+L30+N30+P30+R30+T30+V30+X30+Z30+AB30+AD30+AF30+AH30+AJ30+AL30+AN30+AP30+AR30+AT30+AV30+AX30+AZ30+BB30+BD30+BF30+BH30+BJ30+BL30+BN30+BP30 -> 0 | BS30: 1.92 | BT30: =+BS30*D30 -> 11.52 | BU30: 83000 | BV30: =+BU30*BT30 -> 956160
B31: 48-5004-Điểm | C31: 5.33 | D31: =+C31+BQ31-BR31 -> 5.33 | BQ31: =+E31+G31+I31+K31+M31+O31+Q31+S31+U31+W31+Y31+AA31+AC31+AE31+AG31+AI31+AK31+AM31+AO31+AQ31+AS31+AU31+AW31+AY31+BA31+BC31+BE31+BG31+BI31+BK31+BM31+BO31 -> 0 | BR31: =+F31+H31+J31+L31+N31+P31+R31+T31+V31+X31+Z31+AB31+AD31+AF31+AH31+AJ31+AL31+AN31+AP31+AR31+AT31+AV31+AX31+AZ31+BB31+BD31+BF31+BH31+BJ31+BL31+BN31+BP31 -> 0 | BS31: 1.92 | BT31: =+BS31*D31 -> 10.2336 | BU31: 103000 | BV31: =+BU31*BT31 -> 1054060.8
C32: 0 | D32: =+C32+BQ32-BR32 -> 0 | BQ32: =+E32+G32+I32+K32+M32+O32+Q32+S32+U32+W32+Y32+AA32+AC32+AE32+AG32+AI32+AK32+AM32+AO32+AQ32+AS32+AU32+AW32+AY32+BA32+BC32+BE32+BG32+BI32+BK32+BM32+BO32 -> 0 | BR32: =+F32+H32+J32+L32+N32+P32+R32+T32+V32+X32+Z32+AB32+AD32+AF32+AH32+AJ32+AL32+AN32+AP32+AR32+AT32+AV32+AX32+AZ32+BB32+BD32+BF32+BH32+BJ32+BL32+BN32+BP32 -> 0 | BT32: =+BS32*D32 -> 0 | BV32: =+BU32*BT32 -> 0
A33: 40*80 SV | B33: 48-01 GO | C33: 41.33 | D33: =+C33+BQ33-BR33 -> 41.33 | BQ33: =+E33+G33+I33+K33+M33+O33+Q33+S33+U33+W33+Y33+AA33+AC33+AE33+AG33+AI33+AK33+AM33+AO33+AQ33+AS33+AU33+AW33+AY33+BA33+BC33+BE33+BG33+BI33+BK33+BM33+BO33 -> 0 | BR33: =+F33+H33+J33+L33+N33+P33+R33+T33+V33+X33+Z33+AB33+AD33+AF33+AH33+AJ33+AL33+AN33+AP33+AR33+AT33+AV33+AX33+AZ33+BB33+BD33+BF33+BH33+BJ33+BL33+BN33+BP33 -> 0 | BS33: 1.92 | BT33: =+BS33*D33 -> 79.3536 | BU33: 103000 | BV33: =+BU33*BT33 -> 8173420.8
B34: 48-02 GO | C34: 32 | D34: =+C34+BQ34-BR34 -> 32 | BQ34: =+E34+G34+I34+K34+M34+O34+Q34+S34+U34+W34+Y34+AA34+AC34+AE34+AG34+AI34+AK34+AM34+AO34+AQ34+AS34+AU34+AW34+AY34+BA34+BC34+BE34+BG34+BI34+BK34+BM34+BO34 -> 0 | BR34: =+F34+H34+J34+L34+N34+P34+R34+T34+V34+X34+Z34+AB34+AD34+AF34+AH34+AJ34+AL34+AN34+AP34+AR34+AT34+AV34+AX34+AZ34+BB34+BD34+BF34+BH34+BJ34+BL34+BN34+BP34 -> 0 | BS34: 1.92 | BT34: =+BS34*D34 -> 61.44 | BU34: 103000 | BV34: =+BU34*BT34 -> 6328320
C35: 0 | D35: =+C35+BQ35-BR35 -> 0 | BQ35: =+E35+G35+I35+K35+M35+O35+Q35+S35+U35+W35+Y35+AA35+AC35+AE35+AG35+AI35+AK35+AM35+AO35+AQ35+AS35+AU35+AW35+AY35+BA35+BC35+BE35+BG35+BI35+BK35+BM35+BO35 -> 0 | BR35: =+F35+H35+J35+L35+N35+P35+R35+T35+V35+X35+Z35+AB35+AD35+AF35+AH35+AJ35+AL35+AN35+AP35+AR35+AT35+AV35+AX35+AZ35+BB35+BD35+BF35+BH35+BJ35+BL35+BN35+BP35 -> 0 | BT35: =+BS35*D35 -> 0 | BV35: =+BU35*BT35 -> 0
A36: 50*50 LÁT NỀN | B36: 5-1001 | C36: 200.834 | D36: =+C36+BQ36-BR36 -> 162.834 | X36: 5 | AZ36: 10 | BB36: 1 | BF36: 11 | BL36: 11 | BQ36: =+E36+G36+I36+K36+M36+O36+Q36+S36+U36+W36+Y36+AA36+AC36+AE36+AG36+AI36+AK36+AM36+AO36+AQ36+AS36+AU36+AW36+AY36+BA36+BC36+BE36+BG36+BI36+BK36+BM36+BO36 -> 0 | BR36: =+F36+H36+J36+L36+N36+P36+R36+T36+V36+X36+Z36+AB36+AD36+AF36+AH36+AJ36+AL36+AN36+AP36+AR36+AT36+AV36+AX36+AZ36+BB36+BD36+BF36+BH36+BJ36+BL36+BN36+BP36 -> 38 | BS36: 1.5 | BT36: =+BS36*D36 -> 244.251 | BU36: 61000 | BV36: =+BU36*BT36 -> 14899311
B37: 5-1002 | C37: 333.7 | D37: =+C37+BQ37-BR37 -> 66.7 | R37: 67 | Z37: 7 | AD37: 1 | BJ37: =64+128 -> 192 | BQ37: =+E37+G37+I37+K37+M37+O37+Q37+S37+U37+W37+Y37+AA37+AC37+AE37+AG37+AI37+AK37+AM37+AO37+AQ37+AS37+AU37+AW37+AY37+BA37+BC37+BE37+BG37+BI37+BK37+BM37+BO37 -> 0 | BR37: =+F37+H37+J37+L37+N37+P37+R37+T37+V37+X37+Z37+AB37+AD37+AF37+AH37+AJ37+AL37+AN37+AP37+AR37+AT37+AV37+AX37+AZ37+BB37+BD37+BF37+BH37+BJ37+BL37+BN37+BP37 -> 267 | BS37: 1.5 | BT37: =+BS37*D37 -> 100.05 | BU37: 61000 | BV37: =+BU37*BT37 -> 6103050
B38: 5-1004 | C38: 293.5 | D38: =+C38+BQ38-BR38 -> 293.5 | BQ38: =+E38+G38+I38+K38+M38+O38+Q38+S38+U38+W38+Y38+AA38+AC38+AE38+AG38+AI38+AK38+AM38+AO38+AQ38+AS38+AU38+AW38+AY38+BA38+BC38+BE38+BG38+BI38+BK38+BM38+BO38 -> 0 | BR38: =+F38+H38+J38+L38+N38+P38+R38+T38+V38+X38+Z38+AB38+AD38+AF38+AH38+AJ38+AL38+AN38+AP38+AR38+AT38+AV38+AX38+AZ38+BB38+BD38+BF38+BH38+BJ38+BL38+BN38+BP38 -> 0 | BS38: 1.5 | BT38: =+BS38*D38 -> 440.25 | BU38: 61000 | BV38: =+BU38*BT38 -> 26855250
B39: 5-1007 | C39: 0 | D39: =+C39+BQ39-BR39 -> 0 | BQ39: =+E39+G39+I39+K39+M39+O39+Q39+S39+U39+W39+Y39+AA39+AC39+AE39+AG39+AI39+AK39+AM39+AO39+AQ39+AS39+AU39+AW39+AY39+BA39+BC39+BE39+BG39+BI39+BK39+BM39+BO39 -> 0 | BR39: =+F39+H39+J39+L39+N39+P39+R39+T39+V39+X39+Z39+AB39+AD39+AF39+AH39+AJ39+AL39+AN39+AP39+AR39+AT39+AV39+AX39+AZ39+BB39+BD39+BF39+BH39+BJ39+BL39+BN39+BP39 -> 0 | BS39: 1.5 | BT39: =+BS39*D39 -> 0 | BU39: 61000 | BV39: =+BU39*BT39 -> 0
B40: 5-1012 | C40: 189 | D40: =+C40+BQ40-BR40 -> 132 | R40: 34 | AD40: 2 | AP40: 8 | AR40: 8 | BH40: 7 | BI40: 2 | BQ40: =+E40+G40+I40+K40+M40+O40+Q40+S40+U40+W40+Y40+AA40+AC40+AE40+AG40+AI40+AK40+AM40+AO40+AQ40+AS40+AU40+AW40+AY40+BA40+BC40+BE40+BG40+BI40+BK40+BM40+BO40 -> 2 | BR40: =+F40+H40+J40+L40+N40+P40+R40+T40+V40+X40+Z40+AB40+AD40+AF40+AH40+AJ40+AL40+AN40+AP40+AR40+AT40+AV40+AX40+AZ40+BB40+BD40+BF40+BH40+BJ40+BL40+BN40+BP40 -> 59 | BS40: 1.5 | BT40: =+BS40*D40 -> 198 | BU40: 61000 | BV40: =+BU40*BT40 -> 12078000
...

Sheet NICE
B1: TÊN SP | C1: TỒN CK 30,9.2026 | D1: TỒN HIỆN TẠI T10.2026 | E1: 1 | G1: =1+E1 -> 2 | I1: =1+G1 -> 3 | K1: =1+I1 -> 4 | M1: 5 | O1: =1+M1 -> 6 | Q1: =1+O1 -> 7 | S1: =1+Q1 -> 8 | U1: =1+S1 -> 9 | W1: =1+U1 -> 10 | Y1: =1+W1 -> 11 | AA1: =1+Y1 -> 12 | AC1: =1+AA1 -> 13 | AE1: =1+AC1 -> 14 | AG1: =1+AE1 -> 15 | AI1: =1+AG1 -> 16 | AK1: =1+AI1 -> 17 | AM1: =1+AK1 -> 18 | AO1: =1+AM1 -> 19 | AQ1: =1+AO1 -> 20 | AS1: =1+AQ1 -> 21 | AU1: =1+AS1 -> 22 | AW1: =1+AU1 -> 23 | AY1: =1+AW1 -> 24 | BA1: =1+AY1 -> 25 | BC1: =1+BA1 -> 26 | BE1: =1+BC1 -> 27 | BG1: =1+BE1 -> 28 | BI1: =1+BG1 -> 29 | BK1: =1+BI1 -> 30 | BM1: =1+BK1 -> 31 | BO1: thiếu hụt k rõ nguyên nhân | BQ1: TỔNG | BS1: M2/H | BT1: QUY M2 | BU1: ĐƠN GIÁ/m | BV1: THÀNH TIỀN
A2: TỔNG CỘNG | C2: =SUM(C5:C140) -> 10903.004 | D2: =SUM(D5:D140) -> 10663.004 | E2: N | F2: X | G2: N | H2: X | I2: N | J2: X | K2: N | L2: X | M2: N | N2: X | O2: N | P2: X | Q2: N | R2: X | S2: N | T2: X | U2: N | V2: X | W2: N | X2: X | Y2: N | Z2: X | AA2: N | AB2: X | AC2: N | AD2: X | AE2: N | AF2: X | AG2: N | AH2: X | AI2: N | AJ2: X | AK2: N | AL2: X | AM2: N | AN2: X | AO2: N | AP2: X | AQ2: N | AR2: X | AS2: N | AT2: X | AU2: N | AV2: X | AW2: N | AX2: X | AY2: N | AZ2: X | BA2: N | BB2: X | BC2: N | BD2: X | BE2: N | BF2: X | BG2: N | BH2: X | BI2: N | BJ2: X | BK2: N | BL2: X | BM2: N | BN2: X | BO2: N | BP2: X | BQ2: N | BR2: X | BT2: =SUM(BT5:BT121) -> 18435.463 | BV2: =SUM(BV5:BV121) -> 1.8468104e+09
E3: =SUM(E4:E121) -> 1 | F3: =SUM(F4:F121) -> 33 | G3: =SUM(G4:G121) -> 0 | H3: =SUM(H4:H121) -> 90 | I3: =SUM(I4:I121) -> 0 | J3: =SUM(J4:J121) -> 6 | K3: =SUM(K4:K121) -> 0 | L3: =SUM(L4:L121) -> 29 | ... BP3: =SUM(BP4:BP121) -> 0 | BQ3: =+E3+G3+I3+K3+M3+O3+Q3+S3+U3+W3+Y3+AA3+AC3+AE3+AG3+AI3+AK3+AM3+AO3+AQ3+AS3+AU3+AW3+AY3+BA3+BC3+BE3+BG3+BI3+BK3+BM3+BO3 -> 2 | BR3: =+F3+H3+J3+L3+N3+P3+R3+T3+V3+X3+Z3+AB3+AD3+AF3+AH3+AJ3+AL3+AN3+AP3+AR3+AT3+AV3+AX3+AZ3+BB3+BD3+BF3+BH3+BJ3+BL3+BN3+BP3 -> 242
E4: 0 | BQ4: =+E4+G4+I4+K4+M4+O4+Q4+S4+U4+W4+Y4+AA4+AC4+AE4+AG4+AI4+AK4+AM4+AO4+AQ4+AS4+AU4+AW4+AY4+BA4+BC4+BE4+BG4+BI4+BK4+BM4+BO4 -> 0 | BR4: =+F4+H4+J4+L4+N4+P4+R4+T4+V4+X4+Z4+AB4+AD4+AF4+AH4+AJ4+AL4+AN4+AP4+AR4+AT4+AV4+AX4+AZ4+BB4+BD4+BF4+BH4+BJ4+BL4+BN4+BP4 -> 0
A5: 30*60 BÁN SỨ | B5: 036-6002 Nhạt | C5: 212 | D5: =C5+BQ5-BR5 -> 195 | N5: 17 | BQ5: =+E5+G5+I5+K5+M5+O5+Q5+S5+U5+W5+Y5+AA5+AC5+AE5+AG5+AI5+AK5+AM5+AO5+AQ5+AS5+AU5+AW5+AY5+BA5+BC5+BE5+BG5+BI5+BK5+BM5+BO5 -> 0 | BR5: =+F5+H5+J5+L5+N5+P5+R5+T5+V5+X5+Z5+AB5+AD5+AF5+AH5+AJ5+AL5+AN5+AP5+AR5+AT5+AV5+AX5+AZ5+BB5+BD5+BF5+BH5+BJ5+BL5+BN5+BP5 -> 17 | BS5: 1.44 | BT5: =+BS5*D5 -> 280.8 | BU5: 88000 | BV5: =+BU5*BT5 -> 24710400
B6: 036-6003 nhạt | C6: 53 | D6: =C6+BQ6-BR6 -> 53 | BQ6: =+E6+G6+I6+K6+M6+O6+Q6+S6+U6+W6+Y6+AA6+AC6+AE6+AG6+AI6+AK6+AM6+AO6+AQ6+AS6+AU6+AW6+AY6+BA6+BC6+BE6+BG6+BI6+BK6+BM6+BO6 -> 0 | BR6: =+F6+H6+J6+L6+N6+P6+R6+T6+V6+X6+Z6+AB6+AD6+AF6+AH6+AJ6+AL6+AN6+AP6+AR6+AT6+AV6+AX6+AZ6+BB6+BD6+BF6+BH6+BJ6+BL6+BN6+BP6 -> 0 | BS6: 1.44 | BT6: =+BS6*D6 -> 76.32 | BU6: 88000 | BV6: =+BU6*BT6 -> 6716160
B7: 036-601-kem vàng | C7: 16 | D7: =C7+BQ7-BR7 -> 16 | BQ7: =+E7+G7+I7+K7+M7+O7+Q7+S7+U7+W7+Y7+AA7+AC7+AE7+AG7+AI7+AK7+AM7+AO7+AQ7+AS7+AU7+AW7+AY7+BA7+BC7+BE7+BG7+BI7+BK7+BM7+BO7 -> 0 | BR7: =+F7+H7+J7+L7+N7+P7+R7+T7+V7+X7+Z7+AB7+AD7+AF7+AH7+AJ7+AL7+AN7+AP7+AR7+AT7+AV7+AX7+AZ7+BB7+BD7+BF7+BH7+BJ7+BL7+BN7+BP7 -> 0 | BS7: 1.44 | BT7: =+BS7*D7 -> 23.04 | BU7: 88000 | BV7: =+BU7*BT7 -> 2027520
C8: 0 | D8: =C8+BQ8-BR8 -> 0 | BQ8: =+E8+G8+I8+K8+M8+O8+Q8+S8+U8+W8+Y8+AA8+AC8+AE8+AG8+AI8+AK8+AM8+AO8+AQ8+AS8+AU8+AW8+AY8+BA8+BC8+BE8+BG8+BI8+BK8+BM8+BO8 -> 0 | BR8: =+F8+H8+J8+L8+N8+P8+R8+T8+V8+X8+Z8+AB8+AD8+AF8+AH8+AJ8+AL8+AN8+AP8+AR8+AT8+AV8+AX8+AZ8+BB8+BD8+BF8+BH8+BJ8+BL8+BN8+BP8 -> 0 | BS8: 1.44 | BT8: =+BS8*D8 -> 0 | BU8: 88000 | BV8: =+BU8*BT8 -> 0
A9: 40*80 BỘ BS | B9: 48-6000- Trắng tinh-53(30.12.23) | C9: 6 | D9: =C9+BQ9-BR9 -> 6 | BQ9: =+E9+G9+I9+K9+M9+O9+Q9+S9+U9+W9+Y9+AA9+AC9+AE9+AG9+AI9+AK9+AM9+AO9+AQ9+AS9+AU9+AW9+AY9+BA9+BC9+BE9+BG9+BI9+BK9+BM9+BO9 -> 0 | BR9: =+F9+H9+J9+L9+N9+P9+R9+T9+V9+X9+Z9+AB9+AD9+AF9+AH9+AJ9+AL9+AN9+AP9+AR9+AT9+AV9+AX9+AZ9+BB9+BD9+BF9+BH9+BJ9+BL9+BN9+BP9 -> 0 | BS9: 1.92 | BT9: =+BS9*D9 -> 11.52 | BU9: 105000 | BV9: =+BU9*BT9 -> 1209600
C10: 0 | D10: =C10+BQ10-BR10 -> 0 | BQ10: =+E10+G10+I10+K10+M10+O10+Q10+S10+U10+W10+Y10+AA10+AC10+AE10+AG10+AI10+AK10+AM10+AO10+AQ10+AS10+AU10+AW10+AY10+BA10+BC10+BE10+BG10+BI10+BK10+BM10+BO10 -> 0 | BR10: =+F10+H10+J10+L10+N10+P10+R10+T10+V10+X10+Z10+AB10+AD10+AF10+AH10+AJ10+AL10+AN10+AP10+AR10+AT10+AV10+AX10+AZ10+BB10+BD10+BF10+BH10+BJ10+BL10+BN10+BP10 -> 0 | BS10: 1.92 | BT10: =+BS10*D10 -> 0 | BV10: =+BU10*BT10 -> 0
B11: 48-6001-Nhạt | C11: 111 | D11: =C11+BQ11-BR11 -> 111 | BQ11: =+E11+G11+I11+K11+M11+O11+Q11+S11+U11+W11+Y11+AA11+AC11+AE11+AG11+AI11+AK11+AM11+AO11+AQ11+AS11+AU11+AW11+AY11+BA11+BC11+BE11+BG11+BI11+BK11+BM11+BO11 -> 0 | BR11: =+F11+H11+J11+L11+N11+P11+R11+T11+V11+X11+Z11+AB11+AD11+AF11+AH11+AJ11+AL11+AN11+AP11+AR11+AT11+AV11+AX11+AZ11+BB11+BD11+BF11+BH11+BJ11+BL11+BN11+BP11 -> 0 | BS11: 1.92 | BT11: =+BS11*D11 -> 213.12 | BU11: 101000 | BV11: =+BU11*BT11 -> 21525120
B12: 48-6001-Đậm | C12: 48.67 | D12: =+C12+BQ12-BR12 -> 14.67 | F12: 21 | H12: 13 | BQ12: =+E12+G12+I12+K12+M12+O12+Q12+S12+U12+W12+Y12+AA12+AC12+AE12+AG12+AI12+AK12+AM12+AO12+AQ12+AS12+AU12+AW12+AY12+BA12+BC12+BE12+BG12+BI12+BK12+BM12+BO12 -> 0 | BR12: =+F12+H12+J12+L12+N12+P12+R12+T12+V12+X12+Z12+AB12+AD12+AF12+AH12+AJ12+AL12+AN12+AP12+AR12+AT12+AV12+AX12+AZ12+BB12+BD12+BF12+BH12+BJ12+BL12+BN12+BP12 -> 34 | BS12: 1.92 | BT12: =+BS12*D12 -> 28.1664 | BU12: 106000 | BV12: =+BU12*BT12 -> 2985638.4
B13: 48-6001-Điểm | C13: 40 | D13: =+C13+BQ13-BR13 -> 40 | BQ13: =+E13+G13+I13+K13+M13+O13+Q13+S13+U13+W13+Y13+AA13+AC13+AE13+AG13+AI13+AK13+AM13+AO13+AQ13+AS13+AU13+AW13+AY13+BA13+BC13+BE13+BG13+BI13+BK13+BM13+BO13 -> 0 | BR13: =+F13+H13+J13+L13+N13+P13+R13+T13+V13+X13+Z13+AB13+AD13+AF13+AH13+AJ13+AL13+AN13+AP13+AR13+AT13+AV13+AX13+AZ13+BB13+BD13+BF13+BH13+BJ13+BL13+BN13+BP13 -> 0 | BS13: 1.92 | BT13: =+BS13*D13 -> 76.8 | BU13: 106000 | BV13: =+BU13*BT13 -> 8140800
BQ14: =+E14+G14+I14+K14+M14+O14+Q14+S14+U14+W14+Y14+AA14+AC14+AE14+AG14+AI14+AK14+AM14+AO14+AQ14+AS14+AU14+AW14+AY14+BA14+BC14+BE14+BG14+BI14+BK14+BM14+BO14 -> 0 | BR14: =+F14+H14+J14+L14+N14+P14+R14+T14+V14+X14+Z14+AB14+AD14+AF14+AH14+AJ14+AL14+AN14+AP14+AR14+AT14+AV14+AX14+AZ14+BB14+BD14+BF14+BH14+BJ14+BL14+BN14+BP14 -> 0 | BS14: 1.92 | BT14: =+BS14*D14 -> 0 | BV14: =+BU14*BT14 -> 0
B15: 48-6002-Khói | C15: 89 | D15: =+C15+BQ15-BR15 -> 71 | N15: 18 | BQ15: =+E15+G15+I15+K15+M15+O15+Q15+S15+U15+W15+Y15+AA15+AC15+AE15+AG15+AI15+AK15+AM15+AO15+AQ15+AS15+AU15+AW15+AY15+BA15+BC15+BE15+BG15+BI15+BK15+BM15+BO15 -> 0 | BR15: =+F15+H15+J15+L15+N15+P15+R15+T15+V15+X15+Z15+AB15+AD15+AF15+AH15+AJ15+AL15+AN15+AP15+AR15+AT15+AV15+AX15+AZ15+BB15+BD15+BF15+BH15+BJ15+BL15+BN15+BP15 -> 18 | BS15: 1.92 | BT15: =+BS15*D15 -> 136.32 | BU15: 101000 | BV15: =+BU15*BT15 -> 13768320
B16: 48-6002-Điểm | C16: 6 | D16: =+C16+BQ16-BR16 -> 4 | N16: 2 | BQ16: =+E16+G16+I16+K16+M16+O16+Q16+S16+U16+W16+Y16+AA16+AC16+AE16+AG16+AI16+AK16+AM16+AO16+AQ16+AS16+AU16+AW16+AY16+BA16+BC16+BE16+BG16+BI16+BK16+BM16+BO16 -> 0 | BR16: =+F16+H16+J16+L16+N16+P16+R16+T16+V16+X16+Z16+AB16+AD16+AF16+AH16+AJ16+AL16+AN16+AP16+AR16+AT16+AV16+AX16+AZ16+BB16+BD16+BF16+BH16+BJ16+BL16+BN16+BP16 -> 2 | BS16: 1.92 | BT16: =+BS16*D16 -> 7.68 | BU16: 106000 | BV16: =+BU16*BT16 -> 814080
C17: 0 | D17: =+C17+BQ17-BR17 -> 0 | BQ17: =+E17+G17+I17+K17+M17+O17+Q17+S17+U17+W17+Y17+AA17+AC17+AE17+AG17+AI17+AK17+AM17+AO17+AQ17+AS17+AU17+AW17+AY17+BA17+BC17+BE17+BG17+BI17+BK17+BM17+BO17 -> 0 | BR17: =+F17+H17+J17+L17+N17+P17+R17+T17+V17+X17+Z17+AB17+AD17+AF17+AH17+AJ17+AL17+AN17+AP17+AR17+AT17+AV17+AX17+AZ17+BB17+BD17+BF17+BH17+BJ17+BL17+BN17+BP17 -> 0 | BS17: 1.92 | BT17: =+BS17*D17 -> 0 | BV17: =+BU17*BT17 -> 0
B18: 48-6003-Vân | C18: 90 | D18: =+C18+BQ18-BR18 -> 90 | BQ18: =+E18+G18+I18+K18+M18+O18+Q18+S18+U18+W18+Y18+AA18+AC18+AE18+AG18+AI18+AK18+AM18+AO18+AQ18+AS18+AU18+AW18+AY18+BA18+BC18+BE18+BG18+BI18+BK18+BM18+BO18 -> 0 | BR18: =+F18+H18+J18+L18+N18+P18+R18+T18+V18+X18+Z18+AB18+AD18+AF18+AH18+AJ18+AL18+AN18+AP18+AR18+AT18+AV18+AX18+AZ18+BB18+BD18+BF18+BH18+BJ18+BL18+BN18+BP18 -> 0 | BS18: 1.92 | BT18: =+BS18*D18 -> 172.8 | BU18: 101000 | BV18: =+BU18*BT18 -> 17452800
B19: 48-6003-Điểm | C19: 19 | D19: =+C19+BQ19-BR19 -> 19 | BQ19: =+E19+G19+I19+K19+M19+O19+Q19+S19+U19+W19+Y19+AA19+AC19+AE19+AG19+AI19+AK19+AM19+AO19+AQ19+AS19+AU19+AW19+AY19+BA19+BC19+BE19+BG19+BI19+BK19+BM19+BO19 -> 0 | BR19: =+F19+H19+J19+L19+N19+P19+R19+T19+V19+X19+Z19+AB19+AD19+AF19+AH19+AJ19+AL19+AN19+AP19+AR19+AT19+AV19+AX19+AZ19+BB19+BD19+BF19+BH19+BJ19+BL19+BN19+BP19 -> 0 | BS19: 1.92 | BT19: =+BS19*D19 -> 36.48 | BU19: 106000 | BV19: =+BU19*BT19 -> 3866880
C20: 0 | D20: =+C20+BQ20-BR20 -> 0 | BQ20: =+E20+G20+I20+K20+M20+O20+Q20+S20+U20+W20+Y20+AA20+AC20+AE20+AG20+AI20+AK20+AM20+AO20+AQ20+AS20+AU20+AW20+AY20+BA20+BC20+BE20+BG20+BI20+BK20+BM20+BO20 -> 0 | BR20: =+F20+H20+J20+L20+N20+P20+R20+T20+V20+X20+Z20+AB20+AD20+AF20+AH20+AJ20+AL20+AN20+AP20+AR20+AT20+AV20+AX20+AZ20+BB20+BD20+BF20+BH20+BJ20+BL20+BN20+BP20 -> 0 | BS20: 1.92 | BT20: =+BS20*D20 -> 0 | BV20: =+BU20*BT20 -> 0
B21: 48-6007-Nhạt | C21: 187 | D21: =+C21+BQ21-BR21 -> 187 | BQ21: =+E21+G21+I21+K21+M21+O21+Q21+S21+U21+W21+Y21+AA21+AC21+AE21+AG21+AI21+AK21+AM21+AO21+AQ21+AS21+AU21+AW21+AY21+BA21+BC21+BE21+BG21+BI21+BK21+BM21+BO21 -> 0 | BR21: =+F21+H21+J21+L21+N21+P21+R21+T21+V21+X21+Z21+AB21+AD21+AF21+AH21+AJ21+AL21+AN21+AP21+AR21+AT21+AV21+AX21+AZ21+BB21+BD21+BF21+BH21+BJ21+BL21+BN21+BP21 -> 0 | BS21: 1.92 | BT21: =+BS21*D21 -> 359.04 | BU21: 101000 | BV21: =+BU21*BT21 -> 36263040
B22: 48-6007-Đậm | C22: 63.17 | D22: =+C22+BQ22-BR22 -> 63.17 | BQ22: =+E22+G22+I22+K22+M22+O22+Q22+S22+U22+W22+Y22+AA22+AC22+AE22+AG22+AI22+AK22+AM22+AO22+AQ22+AS22+AU22+AW22+AY22+BA22+BC22+BE22+BG22+BI22+BK22+BM22+BO22 -> 0 | BR22: =+F22+H22+J22+L22+N22+P22+R22+T22+V22+X22+Z22+AB22+AD22+AF22+AH22+AJ22+AL22+AN22+AP22+AR22+AT22+AV22+AX22+AZ22+BB22+BD22+BF22+BH22+BJ22+BL22+BN22+BP22 -> 0 | BS22: 1.92 | BT22: =+BS22*D22 -> 121.2864 | BU22: 106000 | BV22: =+BU22*BT22 -> 12856358
B23: 48-6007-Điểm | C23: 32.66 | D23: =+C23+BQ23-BR23 -> 32.66 | BQ23: =+E23+G23+I23+K23+M23+O23+Q23+S23+U23+W23+Y23+AA23+AC23+AE23+AG23+AI23+AK23+AM23+AO23+AQ23+AS23+AU23+AW23+AY23+BA23+BC23+BE23+BG23+BI23+BK23+BM23+BO23 -> 0 | BR23: =+F23+H23+J23+L23+N23+P23+R23+T23+V23+X23+Z23+AB23+AD23+AF23+AH23+AJ23+AL23+AN23+AP23+AR23+AT23+AV23+AX23+AZ23+BB23+BD23+BF23+BH23+BJ23+BL23+BN23+BP23 -> 0 | BS23: 1.92 | BT23: =+BS23*D23 -> 62.7072 | BU23: 106000 | BV23: =+BU23*BT23 -> 6646963.2
C24: 0 | D24: =+C24+BQ24-BR24 -> 0 | BQ24: =+E24+G24+I24+K24+M24+O24+Q24+S24+U24+W24+Y24+AA24+AC24+AE24+AG24+AI24+AK24+AM24+AO24+AQ24+AS24+AU24+AW24+AY24+BA24+BC24+BE24+BG24+BI24+BK24+BM24+BO24 -> 0 | BR24: =+F24+H24+J24+L24+N24+P24+R24+T24+V24+X24+Z24+AB24+AD24+AF24+AH24+AJ24+AL24+AN24+AP24+AR24+AT24+AV24+AX24+AZ24+BB24+BD24+BF24+BH24+BJ24+BL24+BN24+BP24 -> 0 | BS24: 1.92 | BT24: =+BS24*D24 -> 0 | BV24: =+BU24*BT24 -> 0
B25: 48-5004-Nhạt | C25: 71 | D25: =+C25+BQ25-BR25 -> 71 | BQ25: =+E25+G25+I25+K25+M25+O25+Q25+S25+U25+W25+Y25+AA25+AC25+AE25+AG25+AI25+AK25+AM25+AO25+AQ25+AS25+AU25+AW25+AY25+BA25+BC25+BE25+BG25+BI25+BK25+BM25+BO25 -> 0 | BR25: =+F25+H25+J25+L25+N25+P25+R25+T25+V25+X25+Z25+AB25+AD25+AF25+AH25+AJ25+AL25+AN25+AP25+AR25+AT25+AV25+AX25+AZ25+BB25+BD25+BF25+BH25+BJ25+BL25+BN25+BP25 -> 0 | BS25: 1.92 | BT25: =+BS25*D25 -> 136.32 | BU25: 101000 | BV25: =+BU25*BT25 -> 13768320
B26: 48-5004-Đậm | C26: 4 | D26: =+C26+BQ26-BR26 -> 4 | BQ26: =+E26+G26+I26+K26+M26+O26+Q26+S26+U26+W26+Y26+AA26+AC26+AE26+AG26+AI26+AK26+AM26+AO26+AQ26+AS26+AU26+AW26+AY26+BA26+BC26+BE26+BG26+BI26+BK26+BM26+BO26 -> 0 | BR26: =+F26+H26+J26+L26+N26+P26+R26+T26+V26+X26+Z26+AB26+AD26+AF26+AH26+AJ26+AL26+AN26+AP26+AR26+AT26+AV26+AX26+AZ26+BB26+BD26+BF26+BH26+BJ26+BL26+BN26+BP26 -> 0 | BS26: 1.92 | BT26: =+BS26*D26 -> 7.68 | BU26: 106000 | BV26: =+BU26*BT26 -> 814080
B27: 48-5004-Điểm | C27: 20 | D27: =+C27+BQ27-BR27 -> 9 | E27: 1 | F27: 12 | BQ27: =+E27+G27+I27+K27+M27+O27+Q27+S27+U27+W27+Y27+AA27+AC27+AE27+AG27+AI27+AK27+AM27+AO27+AQ27+AS27+AU27+AW27+AY27+BA27+BC27+BE27+BG27+BI27+BK27+BM27+BO27 -> 1 | BR27: =+F27+H27+J27+L27+N27+P27+R27+T27+V27+X27+Z27+AB27+AD27+AF27+AH27+AJ27+AL27+AN27+AP27+AR27+AT27+AV27+AX27+AZ27+BB27+BD27+BF27+BH27+BJ27+BL27+BN27+BP27 -> 12 | BS27: 1.92 | BT27: =+BS27*D27 -> 17.28 | BU27: 106000 | BV27: =+BU27*BT27 -> 1831680
BQ28: =+E28+G28+I28+K28+M28+O28+Q28+S28+U28+W28+Y28+AA28+AC28+AE28+AG28+AI28+AK28+AM28+AO28+AQ28+AS28+AU28+AW28+AY28+BA28+BC28+BE28+BG28+BI28+BK28+BM28+BO28 -> 0 | BR28: =+F28+H28+J28+L28+N28+P28+R28+T28+V28+X28+Z28+AB28+AD28+AF28+AH28+AJ28+AL28+AN28+AP28+AR28+AT28+AV28+AX28+AZ28+BB28+BD28+BF28+BH28+BJ28+BL28+BN28+BP28 -> 0 | BS28: 1.92 | BT28: =+BS28*D28 -> 0 | BV28: =+BU28*BT28 -> 0
A29: 40*80 SV | B29: 48-01 GO | C29: 41.33 | D29: =+C29+BQ29-BR29 -> 41.33 | BQ29: =+E29+G29+I29+K29+M29+O29+Q29+S29+U29+W29+Y29+AA29+AC29+AE29+AG29+AI29+AK29+AM29+AO29+AQ29+AS29+AU29+AW29+AY29+BA29+BC29+BE29+BG29+BI29+BK29+BM29+BO29 -> 0 | BR29: =+F29+H29+J29+L29+N29+P29+R29+T29+V29+X29+Z29+AB29+AD29+AF29+AH29+AJ29+AL29+AN29+AP29+AR29+AT29+AV29+AX29+AZ29+BB29+BD29+BF29+BH29+BJ29+BL29+BN29+BP29 -> 0 | BS29: 1.92 | BT29: =+BS29*D29 -> 79.3536 | BU29: 106000 | BV29: =+BU29*BT29 -> 8411481.6
B30: 48-02 GO | C30: 32 | D30: =+C30+BQ30-BR30 -> 32 | BQ30: =+E30+G30+I30+K30+M30+O30+Q30+S30+U30+W30+Y30+AA30+AC30+AE30+AG30+AI30+AK30+AM30+AO30+AQ30+AS30+AU30+AW30+AY30+BA30+BC30+BE30+BG30+BI30+BK30+BM30+BO30 -> 0 | BR30: =+F30+H30+J30+L30+N30+P30+R30+T30+V30+X30+Z30+AB30+AD30+AF30+AH30+AJ30+AL30+AN30+AP30+AR30+AT30+AV30+AX30+AZ30+BB30+BD30+BF30+BH30+BJ30+BL30+BN30+BP30 -> 0 | BS30: 1.92 | BT30: =+BS30*D30 -> 61.44 | BU30: 106000 | BV30: =+BU30*BT30 -> 6512640
C31: 0 | D31: =+C31+BQ31-BR31 -> 0 | BQ31: =+E31+G31+I31+K31+M31+O31+Q31+S31+U31+W31+Y31+AA31+AC31+AE31+AG31+AI31+AK31+AM31+AO31+AQ31+AS31+AU31+AW31+AY31+BA31+BC31+BE31+BG31+BI31+BK31+BM31+BO31 -> 0 | BR31: =+F31+H31+J31+L31+N31+P31+R31+T31+V31+X31+Z31+AB31+AD31+AF31+AH31+AJ31+AL31+AN31+AP31+AR31+AT31+AV31+AX31+AZ31+BB31+BD31+BF31+BH31+BJ31+BL31+BN31+BP31 -> 0 | BS31: 1.92 | BT31: =+BS31*D31 -> 0 | BV31: =+BU31*BT31 -> 0
A32: 50*50 LÁT NỀN | B32: 5-1001 | C32: 0.334 | D32: =+C32+BQ32-BR32 -> 0.334 | BQ32: =+E32+G32+I32+K32+M32+O32+Q32+S32+U32+W32+Y32+AA32+AC32+AE32+AG32+AI32+AK32+AM32+AO32+AQ32+AS32+AU32+AW32+AY32+BA32+BC32+BE32+BG32+BI32+BK32+BM32+BO32 -> 0 | BR32: =+F32+H32+J32+L32+N32+P32+R32+T32+V32+X32+Z32+AB32+AD32+AF32+AH32+AJ32+AL32+AN32+AP32+AR32+AT32+AV32+AX32+AZ32+BB32+BD32+BF32+BH32+BJ32+BL32+BN32+BP32 -> 0 | BS32: 1.5 | BT32: =+BS32*D32 -> 0.501 | BU32: 63000 | BV32: =+BU32*BT32 -> 31563
B33: 5-1002 | C33: -0.3 | D33: =+C33+BQ33-BR33 -> -0.3 | BQ33: =+E33+G33+I33+K33+M33+O33+Q33+S33+U33+W33+Y33+AA33+AC33+AE33+AG33+AI33+AK33+AM33+AO33+AQ33+AS33+AU33+AW33+AY33+BA33+BC33+BE33+BG33+BI33+BK33+BM33+BO33 -> 0 | BR33: =+F33+H33+J33+L33+N33+P33+R33+T33+V33+X33+Z33+AB33+AD33+AF33+AH33+AJ33+AL33+AN33+AP33+AR33+AT33+AV33+AX33+AZ33+BB33+BD33+BF33+BH33+BJ33+BL33+BN33+BP33 -> 0 | BS33: 1.5 | BT33: =+BS33*D33 -> -0.45 | BU33: 63000 | BV33: =+BU33*BT33 -> -28350
B34: 5-1004 | C34: 193.5 | D34: =+C34+BQ34-BR34 -> 183.5 | H34: 10 | BQ34: =+E34+G34+I34+K34+M34+O34+Q34+S34+U34+W34+Y34+AA34+AC34+AE34+AG34+AI34+AK34+AM34+AO34+AQ34+AS34+AU34+AW34+AY34+BA34+BC34+BE34+BG34+BI34+BK34+BM34+BO34 -> 0 | BR34: =+F34+H34+J34+L34+N34+P34+R34+T34+V34+X34+Z34+AB34+AD34+AF34+AH34+AJ34+AL34+AN34+AP34+AR34+AT34+AV34+AX34+AZ34+BB34+BD34+BF34+BH34+BJ34+BL34+BN34+BP34 -> 10 | BS34: 1.5 | BT34: =+BS34*D34 -> 275.25 | BU34: 63000 | BV34: =+BU34*BT34 -> 17340750
B35: 5-1012 | C35: 3 | D35: =+C35+BQ35-BR35 -> 3 | BQ35: =+E35+G35+I35+K35+M35+O35+Q35+S35+U35+W35+Y35+AA35+AC35+AE35+AG35+AI35+AK35+AM35+AO35+AQ35+AS35+AU35+AW35+AY35+BA35+BC35+BE35+BG35+BI35+BK35+BM35+BO35 -> 0 | BR35: =+F35+H35+J35+L35+N35+P35+R35+T35+V35+X35+Z35+AB35+AD35+AF35+AH35+AJ35+AL35+AN35+AP35+AR35+AT35+AV35+AX35+AZ35+BB35+BD35+BF35+BH35+BJ35+BL35+BN35+BP35 -> 0 | BS35: 1.5 | BT35: =+BS35*D35 -> 4.5 | BU35: 63000 | BV35: =+BU35*BT35 -> 283500
B36: 5-1501 | C36: 0.33 | D36: =+C36+BQ36-BR36 -> 0.33 | BQ36: =+E36+G36+I36+K36+M36+O36+Q36+S36+U36+W36+Y36+AA36+AC36+AE36+AG36+AI36+AK36+AM36+AO36+AQ36+AS36+AU36+AW36+AY36+BA36+BC36+BE36+BG36+BI36+BK36+BM36+BO36 -> 0 | BR36: =+F36+H36+J36+L36+N36+P36+R36+T36+V36+X36+Z36+AB36+AD36+AF36+AH36+AJ36+AL36+AN36+AP36+AR36+AT36+AV36+AX36+AZ36+BB36+BD36+BF36+BH36+BJ36+BL36+BN36+BP36 -> 0 | BS36: 1.5 | BT36: =+BS36*D36 -> 0.495 | BU36: 65000 | BV36: =+BU36*BT36 -> 32175
B37: 5-1007 | C37: 6.67 | D37: =+C37+BQ37-BR37 -> 6.67 | BQ37: =+E37+G37+I37+K37+M37+O37+Q37+S37+U37+W37+Y37+AA37+AC37+AE37+AG37+AI37+AK37+AM37+AO37+AQ37+AS37+AU37+AW37+AY37+BA37+BC37+BE37+BG37+BI37+BK37+BM37+BO37 -> 0 | BR37: =+F37+H37+J37+L37+N37+P37+R37+T37+V37+X37+Z37+AB37+AD37+AF37+AH37+AJ37+AL37+AN37+AP37+AR37+AT37+AV37+AX37+AZ37+BB37+BD37+BF37+BH37+BJ37+BL37+BN37+BP37 -> 0 | BS37: 1.5 | BT37: =+BS37*D37 -> 10.005 | BV37: =+BU37*BT37 -> 0
A38: 50*50 SÂN VƯỜN | B38: 5-1601 | C38: 22 | D38: =+C38+BQ38-BR38 -> 22 | BQ38: =+E38+G38+I38+K38+M38+O38+Q38+S38+U38+W38+Y38+AA38+AC38+AE38+AG38+AI38+AK38+AM38+AO38+AQ38+AS38+AU38+AW38+AY38+BA38+BC38+BE38+BG38+BI38+BK38+BM38+BO38 -> 0 | BR38: =+F38+H38+J38+L38+N38+P38+R38+T38+V38+X38+Z38+AB38+AD38+AF38+AH38+AJ38+AL38+AN38+AP38+AR38+AT38+AV38+AX38+AZ38+BB38+BD38+BF38+BH38+BJ38+BL38+BN38+BP38 -> 0 | BS38: 1.5 | BT38: =+BS38*D38 -> 33 | BU38: 65000 | BV38: =+BU38*BT38 -> 2145000
B39: 5-1602 | C39: 167 | D39: =+C39+BQ39-BR39 -> 167 | BQ39: =+E39+G39+I39+K39+M39+O39+Q39+S39+U39+W39+Y39+AA39+AC39+AE39+AG39+AI39+AK39+AM39+AO39+AQ39+AS39+AU39+AW39+AY39+BA39+BC39+BE39+BG39+BI39+BK39+BM39+BO39 -> 0 | BR39: =+F39+H39+J39+L39+N39+P39+R39+T39+V39+X39+Z39+AB39+AD39+AF39+AH39+AJ39+AL39+AN39+AP39+AR39+AT39+AV39+AX39+AZ39+BB39+BD39+BF39+BH39+BJ39+BL39+BN39+BP39 -> 0 | BS39: 1.5 | BT39: =+BS39*D39 -> 250.5 | BU39: 65000 | BV39: =+BU39*BT39 -> 16282500
B40: 5-1603 | C40: 204 | D40: =+C40+BQ40-BR40 -> 204 | BQ40: =+E40+G40+I40+K40+M40+O40+Q40+S40+U40+W40+Y40+AA40+AC40+AE40+AG40+AI40+AK40+AM40+AO40+AQ40+AS40+AU40+AW40+AY40+BA40+BC40+BE40+BG40+BI40+BK40+BM40+BO40 -> 0 | BR40: =+F40+H40+J40+L40+N40+P40+R40+T40+V40+X40+Z40+AB40+AD40+AF40+AH40+AJ40+AL40+AN40+AP40+AR40+AT40+AV40+AX40+AZ40+BB40+BD40+BF40+BH40+BJ40+BL40+BN40+BP40 -> 0 | BS40: 1.5 | BT40: =+BS40*D40 -> 306 | BU40: 65000 | BV40: =+BU40*BT40 -> 19890000
...

Sheet RA+AD
B1: MÃ SP | C1: TỒN CK 30.6.2026 | D1: TỒN HIỆN TẠI T7.2026 | E1: 1 | G1: =1+E1 -> 2 | I1: =1+G1 -> 3 | K1: =1+I1 -> 4 | M1: =1+K1 -> 5 | O1: =1+M1 -> 6 | Q1: =1+O1 -> 7 | S1: =1+Q1 -> 8 | U1: =1+S1 -> 9 | W1: =1+U1 -> 10 | Y1: =1+W1 -> 11 | AA1: =1+Y1 -> 12 | AC1: =1+AA1 -> 13 | AE1: =1+AC1 -> 14 | AG1: =1+AE1 -> 15 | AI1: =1+AG1 -> 16 | AK1: =1+AI1 -> 17 | AM1: =1+AK1 -> 18 | AO1: =1+AM1 -> 19 | AQ1: =1+AO1 -> 20 | AS1: =1+AQ1 -> 21 | AU1: =1+AS1 -> 22 | AW1: =1+AU1 -> 23 | AY1: =1+AW1 -> 24 | BA1: =1+AY1 -> 25 | BC1: =1+BA1 -> 26 | BE1: =1+BC1 -> 27 | BG1: =1+BE1 -> 28 | BI1: =1+BG1 -> 29 | BK1: =1+BI1 -> 30 | BM1: =1+BK1 -> 31 | BO1: Thiếu thừa chưa ro nguyên nhân | BQ1: TỔNG | BS1: M2/H | BT1: QUY M2 | BU1: ĐƠN GIÁ | BV1: THÀNH TIỀN
